Workbook

Sheet Instructions
A2: JOBPLANNER → ALLEATO COMMITMENT CONVERTER
A4: This workbook helps you convert your JobPlanner commitment export into Alleato's import format.
A6: HOW TO USE
A9: STEP 1: Paste your JobPlanner CSV data into the 'JobPlanner Data' sheet
A10: - Open your JobPlanner export CSV file
A11: - Copy the entire contents (all columns and rows)
A12: - Paste into the 'JobPlanner Data' sheet starting at cell A1
A14: STEP 2: Create a Company Lookup table in the 'Company Lookup' sheet
A15: - Column A: Vendor names (from your JobPlanner data)
A16: - Column B: Company UUIDs (from Alleato Directory → Companies)
A17: - This maps vendor names to their Alleato company IDs
A19: STEP 3: The 'Transformation' sheet will auto-convert your data
... A36: COLUMN MAPPING
A37: JobPlanner Column | B37: Maps To | C37: Transformation
A38: Number | B38: Number | C38: Direct copy
A39: Type | B39: Type | C39: Direct copy (lowercase)
A40: Contracted Company | B40: Company ID | C40: VLOOKUP from Company Lookup table
A41: Title | B41: Title | C41: Use this if not blank; otherwise use Category column
A42: Cost Code (col 5) | B42: Budget Code | C42: Goes to SOV Items sheet
A43: Category (col 6) | B43: Description | C43: Used if Title is blank
A44: Amount | B44: Original Amount | C44: Remove $ and commas
A45: Retainage | B45: Retention Percentage | C45: Direct copy
A46: Contract Date | B46: Contract Date | C46: Convert MM/DD/YYYY to YYYY-MM-DD
A47: Status | B47: Status | C47: Convert to lowercase
A48: Description | B48: Description | C48: Direct copy
... A52: Exclusions | B52: Exclusions | C52: Direct copy

Sheet Company Lookup
A1: Vendor Name from JobPlanner | B1: Company UUID from Alleato
A2: ← Paste vendor names here | Paste UUIDs here →
A3: C&S Heating & Cooling Inc.
A4: Casework Concepts LLC
A5: Central Indiana Hardware, CO, Inc
A6: Superior Contractors Inc
A7: Deem, LLC
A8: Justin Dorsey Plumbing
A9: EURO Plastering
A10: Steel Services, Inc
A11: Bul-Tec Roofing
A12: KLEENIT GROUP INC.
A13: Inline Painting LLC
... A20: Apex Glass LLC

Sheet JobPlanner Data
A1: ← Paste your entire JobPlanner CSV export here
A2: Number | B2: Type | C2: Contracted Company | D2: Title | E2: Col5 | F2: Col6 | G2: Amount | H2: Retainage | I2: Contract Date | J2: Status | K2: Created | L2: Description | M2: Delivery | N2: Start | O2: Inclusions | P2: Exclusions | Q2: Est. Complete | R2: Act. Complete | S2: Signed Date | T2: Execution Date | U2: Issued On | V2: Returned On | W2: Payment Terms | X2: Shipping Info

Sheet Transformation
A1: Number | B1: Type | C1: Title | D1: Status | E1: Company ID | F1: Original Amount | G1: Accounting Method | H1: Description | I1: Retention Percentage | J1: Start Date | K1: Est. Completion Date | L1: Contract Date | M1: Signed Date | N1: Actual Completion Date | O1: Issued On Date | P1: Inclusions | Q1: Exclusions
A2: =IF('JobPlanner Data'!A3="","",IF(ISBLANK('JobPlanner Data'!A3),"",'JobPlanner Data'!A3)) | B2: =IF('JobPlanner Data'!B3="","",LOWER('JobPlanner Data'!B3)) | C2: =IF('JobPlanner Data'!D3<>"","JobPlanner Data'!D3,IF('JobPlanner Data'!F3<>"","JobPlanner Data'!F3,"")) | D2: =IF('JobPlanner Data'!J3="","",LOWER('JobPlanner Data'!J3)) | E2: =IF('JobPlanner Data'!C3="","",IFERROR(VLOOKUP('JobPlanner Data'!C3,'Company Lookup'!A:B,2,FALSE),"[NOT FOUND]")) | F2: =IF('JobPlanner Data'!G3="","",VALUE(SUBSTITUTE(SUBSTITUTE('JobPlanner Data'!G3,"$",""),",",""))) | G2: ="amount" | H2: =IF('JobPlanner Data'!L3="","","JobPlanner Data'!L3) | I2: =IF('JobPlanner Data'!H3="","","JobPlanner Data'!H3) | J2: =IF('JobPlanner Data'!N3="","",IF(ISNUMBER('JobPlanner Data'!N3),TEXT('JobPlanner Data'!N3,"YYYY-MM-DD"),"")) | K2: =IF('JobPlanner Data'!Q3="","",IF(ISNUMBER('JobPlanner Data'!Q3),TEXT('JobPlanner Data'!Q3,"YYYY-MM-DD"),"")) | L2: =IF('JobPlanner Data'!I3<>"",IF(ISNUMBER('JobPlanner Data'!I3),TEXT('JobPlanner Data'!I3,"YYYY-MM-DD"),""),IF('JobPlanner Data'!T3<>"",IF(ISNUMBER('JobPlanner Data'!T3),TEXT('JobPlanner Data'!T3,"YYYY-MM-DD"),""),"")) | M2: =IF('JobPlanner Data'!S3="","",IF(ISNUMBER('JobPlanner Data'!S3),TEXT('JobPlanner Data'!S3,"YYYY-MM-DD"),"")) | N2: =IF('JobPlanner Data'!R3="","",IF(ISNUMBER('JobPlanner Data'!R3),TEXT('JobPlanner Data'!R3,"YYYY-MM-DD"),"")) | O2: =IF('JobPlanner Data'!U3="","",IF(ISNUMBER('JobPlanner Data'!U3),TEXT('JobPlanner Data'!U3,"YYYY-MM-DD"),"")) | P2: =IF('JobPlanner Data'!O3="","","JobPlanner Data'!O3) | Q2: =IF('JobPlanner Data'!P3="","","JobPlanner Data'!P3)
A3: =IF('JobPlanner Data'!A4="","",IF(ISBLANK('JobPlanner Data'!A4),"",'JobPlanner Data'!A4)) | B3: =IF('JobPlanner Data'!B4="","",LOWER('JobPlanner Data'!B4)) | C3: =IF('JobPlanner Data'!D4<>"","JobPlanner Data'!D4,IF('JobPlanner Data'!F4<>"","JobPlanner Data'!F4,"")) | D3: =IF('JobPlanner Data'!J4="","",LOWER('JobPlanner Data'!J4)) | E3: =IF('JobPlanner Data'!C4="","",IFERROR(VLOOKUP('JobPlanner Data'!C4,'Company Lookup'!A:B,2,FALSE),"[NOT FOUND]")) | F3: =IF('JobPlanner Data'!G4="","",VALUE(SUBSTITUTE(SUBSTITUTE('JobPlanner Data'!G4,"$",""),",",""))) | G3: ="amount" | H3: =IF('JobPlanner Data'!L4="","","JobPlanner Data'!L4) | I3: =IF('JobPlanner Data'!H4="","","JobPlanner Data'!H4) | J3: =IF('JobPlanner Data'!N4="","",IF(ISNUMBER('JobPlanner Data'!N4),TEXT('JobPlanner Data'!N4,"YYYY-MM-DD"),"")) | K3: =IF('JobPlanner Data'!Q4="","",IF(ISNUMBER('JobPlanner Data'!Q4),TEXT('JobPlanner Data'!Q4,"YYYY-MM-DD"),"")) | L3: =IF('JobPlanner Data'!I4<>"",IF(ISNUMBER('JobPlanner Data'!I4),TEXT('JobPlanner Data'!I4,"YYYY-MM-DD"),""),IF('JobPlanner Data'!T4<>"",IF(ISNUMBER('JobPlanner Data'!T4),TEXT('JobPlanner Data'!T4,"YYYY-MM-DD"),""),"")) | M3: =IF('JobPlanner Data'!S4="","",IF(ISNUMBER('JobPlanner Data'!S4),TEXT('JobPlanner Data'!S4,"YYYY-MM-DD"),"")) | N3: =IF('JobPlanner Data'!R4="","",IF(ISNUMBER('JobPlanner Data'!R4),TEXT('JobPlanner Data'!R4,"YYYY-MM-DD"),"")) | O3: =IF('JobPlanner Data'!U4="","",IF(ISNUMBER('JobPlanner Data'!U4),TEXT('JobPlanner Data'!U4,"YYYY-MM-DD"),"")) | P3: =IF('JobPlanner Data'!O4="","","JobPlanner Data'!O4) | Q3: =IF('JobPlanner Data'!P4="","","JobPlanner Data'!P4)
A4: =IF('JobPlanner Data'!A5="","",IF(ISBLANK('JobPlanner Data'!A5),"",'JobPlanner Data'!A5)) | B4: =IF('JobPlanner Data'!B5="","",LOWER('JobPlanner Data'!B5)) | C4: =IF('JobPlanner Data'!D5<>"","JobPlanner Data'!D5,IF('JobPlanner Data'!F5<>"","JobPlanner Data'!F5,"")) | D4: =IF('JobPlanner Data'!J5="","",LOWER('JobPlanner Data'!J5)) | E4: =IF('JobPlanner Data'!C5="","",IFERROR(VLOOKUP('JobPlanner Data'!C5,'Company Lookup'!A:B,2,FALSE),"[NOT FOUND]")) | F4: =IF('JobPlanner Data'!G5="","",VALUE(SUBSTITUTE(SUBSTITUTE('JobPlanner Data'!G5,"$",""),",",""))) | G4: ="amount" | H4: =IF('JobPlanner Data'!L5="","","JobPlanner Data'!L5) | I4: =IF('JobPlanner Data'!H5="","","JobPlanner Data'!H5) | J4: =IF('JobPlanner Data'!N5="","",IF(ISNUMBER('JobPlanner Data'!N5),TEXT('JobPlanner Data'!N5,"YYYY-MM-DD"),"")) | K4: =IF('JobPlanner Data'!Q5="","",IF(ISNUMBER('JobPlanner Data'!Q5),TEXT('JobPlanner Data'!Q5,"YYYY-MM-DD"),"")) | L4: =IF('JobPlanner Data'!I5<>"",IF(ISNUMBER('JobPlanner Data'!I5),TEXT('JobPlanner Data'!I5,"YYYY-MM-DD"),""),IF('JobPlanner Data'!T5<>"",IF(ISNUMBER('JobPlanner Data'!T5),TEXT('JobPlanner Data'!T5,"YYYY-MM-DD"),""),"")) | M4: =IF('JobPlanner Data'!S5="","",IF(ISNUMBER('JobPlanner Data'!S5),TEXT('JobPlanner Data'!S5,"YYYY-MM-DD"),"")) | N4: =IF('JobPlanner Data'!R5="","",IF(ISNUMBER('JobPlanner Data'!R5),TEXT('JobPlanner Data'!R5,"YYYY-MM-DD"),"")) | O4: =IF('JobPlanner Data'!U5="","",IF(ISNUMBER('JobPlanner Data'!U5),TEXT('JobPlanner Data'!U5,"YYYY-MM-DD"),"")) | P4: =IF('JobPlanner Data'!O5="","","JobPlanner Data'!O5) | Q4: =IF('JobPlanner Data'!P5="","","JobPlanner Data'!P5)
A5: =IF('JobPlanner Data'!A6="","",IF(ISBLANK('JobPlanner Data'!A6),"",'JobPlanner Data'!A6)) | B5: =IF('JobPlanner Data'!B6="","",LOWER('JobPlanner Data'!B6)) | C5: =IF('JobPlanner Data'!D6<>"","JobPlanner Data'!D6,IF('JobPlanner Data'!F6<>"","JobPlanner Data'!F6,"")) | D5: =IF('JobPlanner Data'!J6="","",LOWER('JobPlanner Data'!J6)) | E5: =IF('JobPlanner Data'!C6="","",IFERROR(VLOOKUP('JobPlanner Data'!C6,'Company Lookup'!A:B,2,FALSE),"[NOT FOUND]")) | F5: =IF('JobPlanner Data'!G6="","",VALUE(SUBSTITUTE(SUBSTITUTE('JobPlanner Data'!G6,"$",""),",",""))) | G5: ="amount" | H5: =IF('JobPlanner Data'!L6="","","JobPlanner Data'!L6) | I5: =IF('JobPlanner Data'!H6="","","JobPlanner Data'!H6) | J5: =IF('JobPlanner Data'!N6="","",IF(ISNUMBER('JobPlanner Data'!N6),TEXT('JobPlanner Data'!N6,"YYYY-MM-DD"),"")) | K5: =IF('JobPlanner Data'!Q6="","",IF(ISNUMBER('JobPlanner Data'!Q6),TEXT('JobPlanner Data'!Q6,"YYYY-MM-DD"),"")) | L5: =IF('JobPlanner Data'!I6<>"",IF(ISNUMBER('JobPlanner Data'!I6),TEXT('JobPlanner Data'!I6,"YYYY-MM-DD"),""),IF('JobPlanner Data'!T6<>"",IF(ISNUMBER('JobPlanner Data'!T6),TEXT('JobPlanner Data'!T6,"YYYY-MM-DD"),""),"")) | M5: =IF('JobPlanner Data'!S6="","",IF(ISNUMBER('JobPlanner Data'!S6),TEXT('JobPlanner Data'!S6,"YYYY-MM-DD"),"")) | N5: =IF('JobPlanner Data'!R6="","",IF(ISNUMBER('JobPlanner Data'!R6),TEXT('JobPlanner Data'!R6,"YYYY-MM-DD"),"")) | O5: =IF('JobPlanner Data'!U6="","",IF(ISNUMBER('JobPlanner Data'!U6),TEXT('JobPlanner Data'!U6,"YYYY-MM-DD"),"")) | P5: =IF('JobPlanner Data'!O6="","","JobPlanner Data'!O6) | Q5: =IF('JobPlanner Data'!P6="","","JobPlanner Data'!P6)
A6: =IF('JobPlanner Data'!A7="","",IF(ISBLANK('JobPlanner Data'!A7),"",'JobPlanner Data'!A7)) | B6: =IF('JobPlanner Data'!B7="","",LOWER('JobPlanner Data'!B7)) | C6: =IF('JobPlanner Data'!D7<>"","JobPlanner Data'!D7,IF('JobPlanner Data'!F7<>"","JobPlanner Data'!F7,"")) | D6: =IF('JobPlanner Data'!J7="","",LOWER('JobPlanner Data'!J7)) | E6: =IF('JobPlanner Data'!C7="","",IFERROR(VLOOKUP('JobPlanner Data'!C7,'Company Lookup'!A:B,2,FALSE),"[NOT FOUND]")) | F6: =IF('JobPlanner Data'!G7="","",VALUE(SUBSTITUTE(SUBSTITUTE('JobPlanner Data'!G7,"$",""),",",""))) | G6: ="amount" | H6: =IF('JobPlanner Data'!L7="","","JobPlanner Data'!L7) | I6: =IF('JobPlanner Data'!H7="","","JobPlanner Data'!H7) | J6: =IF('JobPlanner Data'!N7="","",IF(ISNUMBER('JobPlanner Data'!N7),TEXT('JobPlanner Data'!N7,"YYYY-MM-DD"),"")) | K6: =IF('JobPlanner Data'!Q7="","",IF(ISNUMBER('JobPlanner Data'!Q7),TEXT('JobPlanner Data'!Q7,"YYYY-MM-DD"),"")) | L6: =IF('JobPlanner Data'!I7<>"",IF(ISNUMBER('JobPlanner Data'!I7),TEXT('JobPlanner Data'!I7,"YYYY-MM-DD"),""),IF('JobPlanner Data'!T7<>"",IF(ISNUMBER('JobPlanner Data'!T7),TEXT('JobPlanner Data'!T7,"YYYY-MM-DD"),""),"")) | M6: =IF('JobPlanner Data'!S7="","",IF(ISNUMBER('JobPlanner Data'!S7),TEXT('JobPlanner Data'!S7,"YYYY-MM-DD"),"")) | N6: =IF('JobPlanner Data'!R7="","",IF(ISNUMBER('JobPlanner Data'!R7),TEXT('JobPlanner Data'!R7,"YYYY-MM-DD"),"")) | O6: =IF('JobPlanner Data'!U7="","",IF(ISNUMBER('JobPlanner Data'!U7),TEXT('JobPlanner Data'!U7,"YYYY-MM-DD"),"")) | P6: =IF('JobPlanner Data'!O7="","","JobPlanner Data'!O7) | Q6: =IF('JobPlanner Data'!P7="","","JobPlanner Data'!P7)
A7: =IF('JobPlanner Data'!A8="","",IF(ISBLANK('JobPlanner Data'!A8),"",'JobPlanner Data'!A8)) | B7: =IF('JobPlanner Data'!B8="","",LOWER('JobPlanner Data'!B8)) | C7: =IF('JobPlanner Data'!D8<>"","JobPlanner Data'!D8,IF('JobPlanner Data'!F8<>"","JobPlanner Data'!F8,"")) | D7: =IF('JobPlanner Data'!J8="","",LOWER('JobPlanner Data'!J8)) | E7: =IF('JobPlanner Data'!C8="","",IFERROR(VLOOKUP('JobPlanner Data'!C8,'Company Lookup'!A:B,2,FALSE),"[NOT FOUND]")) | F7: =IF('JobPlanner Data'!G8="","",VALUE(SUBSTITUTE(SUBSTITUTE('JobPlanner Data'!G8,"$",""),",",""))) | G7: ="amount" | H7: =IF('JobPlanner Data'!L8="","","JobPlanner Data'!L8) | I7: =IF('JobPlanner Data'!H8="","","JobPlanner Data'!H8) | J7: =IF('JobPlanner Data'!N8="","",IF(ISNUMBER('JobPlanner Data'!N8),TEXT('JobPlanner Data'!N8,"YYYY-MM-DD"),"")) | K7: =IF('JobPlanner Data'!Q8="","",IF(ISNUMBER('JobPlanner Data'!Q8),TEXT('JobPlanner Data'!Q8,"YYYY-MM-DD"),"")) | L7: =IF('JobPlanner Data'!I8<>"",IF(ISNUMBER('JobPlanner Data'!I8),TEXT('JobPlanner Data'!I8,"YYYY-MM-DD"),""),IF('JobPlanner Data'!T8<>"",IF(ISNUMBER('JobPlanner Data'!T8),TEXT('JobPlanner Data'!T8,"YYYY-MM-DD"),""),"")) | M7: =IF('JobPlanner Data'!S8="","",IF(ISNUMBER('JobPlanner Data'!S8),TEXT('JobPlanner Data'!S8,"YYYY-MM-DD"),"")) | N7: =IF('JobPlanner Data'!R8="","",IF(ISNUMBER('JobPlanner Data'!R8),TEXT('JobPlanner Data'!R8,"YYYY-MM-DD"),"")) | O7: =IF('JobPlanner Data'!U8="","",IF(ISNUMBER('JobPlanner Data'!U8),TEXT('JobPlanner Data'!U8,"YYYY-MM-DD"),"")) | P7: =IF('JobPlanner Data'!O8="","","JobPlanner Data'!O8) | Q7: =IF('JobPlanner Data'!P8="","","JobPlanner Data'!P8)
A8: =IF('JobPlanner Data'!A9="","",IF(ISBLANK('JobPlanner Data'!A9),"",'JobPlanner Data'!A9)) | B8: =IF('JobPlanner Data'!B9="","",LOWER('JobPlanner Data'!B9)) | C8: =IF('JobPlanner Data'!D9<>"","JobPlanner Data'!D9,IF('JobPlanner Data'!F9<>"","JobPlanner Data'!F9,"")) | D8: =IF('JobPlanner Data'!J9="","",LOWER('JobPlanner Data'!J9)) | E8: =IF('JobPlanner Data'!C9="","",IFERROR(VLOOKUP('JobPlanner Data'!C9,'Company Lookup'!A:B,2,FALSE),"[NOT FOUND]")) | F8: =IF('JobPlanner Data'!G9="","",VALUE(SUBSTITUTE(SUBSTITUTE('JobPlanner Data'!G9,"$",""),",",""))) | G8: ="amount" | H8: =IF('JobPlanner Data'!L9="","","JobPlanner Data'!L9) | I8: =IF('JobPlanner Data'!H9="","","JobPlanner Data'!H9) | J8: =IF('JobPlanner Data'!N9="","",IF(ISNUMBER('JobPlanner Data'!N9),TEXT('JobPlanner Data'!N9,"YYYY-MM-DD"),"")) | K8: =IF('JobPlanner Data'!Q9="","",IF(ISNUMBER('JobPlanner Data'!Q9),TEXT('JobPlanner Data'!Q9,"YYYY-MM-DD"),"")) | L8: =IF('JobPlanner Data'!I9<>"",IF(ISNUMBER('JobPlanner Data'!I9),TEXT('JobPlanner Data'!I9,"YYYY-MM-DD"),""),IF('JobPlanner Data'!T9<>"",IF(ISNUMBER('JobPlanner Data'!T9),TEXT('JobPlanner Data'!T9,"YYYY-MM-DD"),""),"")) | M8: =IF('JobPlanner Data'!S9="","",IF(ISNUMBER('JobPlanner Data'!S9),TEXT('JobPlanner Data'!S9,"YYYY-MM-DD"),"")) | N8: =IF('JobPlanner Data'!R9="","",IF(ISNUMBER('JobPlanner Data'!R9),TEXT('JobPlanner Data'!R9,"YYYY-MM-DD"),"")) | O8: =IF('JobPlanner Data'!U9="","",IF(ISNUMBER('JobPlanner Data'!U9),TEXT('JobPlanner Data'!U9,"YYYY-MM-DD"),"")) | P8: =IF('JobPlanner Data'!O9="","","JobPlanner Data'!O9) | Q8: =IF('JobPlanner Data'!P9="","","JobPlanner Data'!P9)
A9: =IF('JobPlanner Data'!A10="","",IF(ISBLANK('JobPlanner Data'!A10),"",'JobPlanner Data'!A10)) | B9: =IF('JobPlanner Data'!B10="","",LOWER('JobPlanner Data'!B10)) | C9: =IF('JobPlanner Data'!D10<>"","JobPlanner Data'!D10,IF('JobPlanner Data'!F10<>"","JobPlanner Data'!F10,"")) | D9: =IF('JobPlanner Data'!J10="","",LOWER('JobPlanner Data'!J10)) | E9: =IF('JobPlanner Data'!C10="","",IFERROR(VLOOKUP('JobPlanner Data'!C10,'Company Lookup'!A:B,2,FALSE),"[NOT FOUND]")) | F9: =IF('JobPlanner Data'!G10="","",VALUE(SUBSTITUTE(SUBSTITUTE('JobPlanner Data'!G10,"$",""),",",""))) | G9: ="amount" | H9: =IF('JobPlanner Data'!L10="","","JobPlanner Data'!L10) | I9: =IF('JobPlanner Data'!H10="","","JobPlanner Data'!H10) | J9: =IF('JobPlanner Data'!N10="","",IF(ISNUMBER('JobPlanner Data'!N10),TEXT('JobPlanner Data'!N10,"YYYY-MM-DD"),"")) | K9: =IF('JobPlanner Data'!Q10="","",IF(ISNUMBER('JobPlanner Data'!Q10),TEXT('JobPlanner Data'!Q10,"YYYY-MM-DD"),"")) | L9: =IF('JobPlanner Data'!I10<>"",IF(ISNUMBER('JobPlanner Data'!I10),TEXT('JobPlanner Data'!I10,"YYYY-MM-DD"),""),IF('JobPlanner Data'!T10<>"",IF(ISNUMBER('JobPlanner Data'!T10),TEXT('JobPlanner Data'!T10,"YYYY-MM-DD"),""),"")) | M9: =IF('JobPlanner Data'!S10="","",IF(ISNUMBER('JobPlanner Data'!S10),TEXT('JobPlanner Data'!S10,"YYYY-MM-DD"),"")) | N9: =IF('JobPlanner Data'!R10="","",IF(ISNUMBER('JobPlanner Data'!R10),TEXT('JobPlanner Data'!R10,"YYYY-MM-DD"),"")) | O9: =IF('JobPlanner Data'!U10="","",IF(ISNUMBER('JobPlanner Data'!U10),TEXT('JobPlanner Data'!U10,"YYYY-MM-DD"),"")) | P9: =IF('JobPlanner Data'!O10="","","JobPlanner Data'!O10) | Q9: =IF('JobPlanner Data'!P10="","","JobPlanner Data'!P10)
A10: =IF('JobPlanner Data'!A11="","",IF(ISBLANK('JobPlanner Data'!A11),"",'JobPlanner Data'!A11)) | B10: =IF('JobPlanner Data'!B11="","",LOWER('JobPlanner Data'!B11)) | C10: =IF('JobPlanner Data'!D11<>"","JobPlanner Data'!D11,IF('JobPlanner Data'!F11<>"","JobPlanner Data'!F11,"")) | D10: =IF('JobPlanner Data'!J11="","",LOWER('JobPlanner Data'!J11)) | E10: =IF('JobPlanner Data'!C11="","",IFERROR(VLOOKUP('JobPlanner Data'!C11,'Company Lookup'!A:B,2,FALSE),"[NOT FOUND]")) | F10: =IF('JobPlanner Data'!G11="","",VALUE(SUBSTITUTE(SUBSTITUTE('JobPlanner Data'!G11,"$",""),",",""))) | G10: ="amount" | H10: =IF('JobPlanner Data'!L11="","","JobPlanner Data'!L11) | I10: =IF('JobPlanner Data'!H11="","","JobPlanner Data'!H11) | J10: =IF('JobPlanner Data'!N11="","",IF(ISNUMBER('JobPlanner Data'!N11),TEXT('JobPlanner Data'!N11,"YYYY-MM-DD"),"")) | K10: =IF('JobPlanner Data'!Q11="","",IF(ISNUMBER('JobPlanner Data'!Q11),TEXT('JobPlanner Data'!Q11,"YYYY-MM-DD"),"")) | L10: =IF('JobPlanner Data'!I11<>"",IF(ISNUMBER('JobPlanner Data'!I11),TEXT('JobPlanner Data'!I11,"YYYY-MM-DD"),""),IF('JobPlanner Data'!T11<>"",IF(ISNUMBER('JobPlanner Data'!T11),TEXT('JobPlanner Data'!T11,"YYYY-MM-DD"),""),"")) | M10: =IF('JobPlanner Data'!S11="","",IF(ISNUMBER('JobPlanner Data'!S11),TEXT('JobPlanner Data'!S11,"YYYY-MM-DD"),"")) | N10: =IF('JobPlanner Data'!R11="","",IF(ISNUMBER('JobPlanner Data'!R11),TEXT('JobPlanner Data'!R11,"YYYY-MM-DD"),"")) | O10: =IF('JobPlanner Data'!U11="","",IF(ISNUMBER('JobPlanner Data'!U11),TEXT('JobPlanner Data'!U11,"YYYY-MM-DD"),"")) | P10: =IF('JobPlanner Data'!O11="","","JobPlanner Data'!O11) | Q10: =IF('JobPlanner Data'!P11="","","JobPlanner Data'!P11)
A11: =IF('JobPlanner Data'!A12="","",IF(ISBLANK('JobPlanner Data'!A12),"",'JobPlanner Data'!A12)) | B11: =IF('JobPlanner Data'!B12="","",LOWER('JobPlanner Data'!B12)) | C11: =IF('JobPlanner Data'!D12<>"","JobPlanner Data'!D12,IF('JobPlanner Data'!F12<>"","JobPlanner Data'!F12,"")) | D11: =IF('JobPlanner Data'!J12="","",LOWER('JobPlanner Data'!J12)) | E11: =IF('JobPlanner Data'!C12="","",IFERROR(VLOOKUP('JobPlanner Data'!C12,'Company Lookup'!A:B,2,FALSE),"[NOT FOUND]")) | F11: =IF('JobPlanner Data'!G12="","",VALUE(SUBSTITUTE(SUBSTITUTE('JobPlanner Data'!G12,"$",""),",",""))) | G11: ="amount" | H11: =IF('JobPlanner Data'!L12="","","JobPlanner Data'!L12) | I11: =IF('JobPlanner Data'!H12="","","JobPlanner Data'!H12) | J11: =IF('JobPlanner Data'!N12="","",IF(ISNUMBER('JobPlanner Data'!N12),TEXT('JobPlanner Data'!N12,"YYYY-MM-DD"),"")) | K11: =IF('JobPlanner Data'!Q12="","",IF(ISNUMBER('JobPlanner Data'!Q12),TEXT('JobPlanner Data'!Q12,"YYYY-MM-DD"),"")) | L11: =IF('JobPlanner Data'!I12<>"",IF(ISNUMBER('JobPlanner Data'!I12),TEXT('JobPlanner Data'!I12,"YYYY-MM-DD"),""),IF('JobPlanner Data'!T12<>"",IF(ISNUMBER('JobPlanner Data'!T12),TEXT('JobPlanner Data'!T12,"YYYY-MM-DD"),""),"")) | M11: =IF('JobPlanner Data'!S12="","",IF(ISNUMBER('JobPlanner Data'!S12),TEXT('JobPlanner Data'!S12,"YYYY-MM-DD"),"")) | N11: =IF('JobPlanner Data'!R12="","",IF(ISNUMBER('JobPlanner Data'!R12),TEXT('JobPlanner Data'!R12,"YYYY-MM-DD"),"")) | O11: =IF('JobPlanner Data'!U12="","",IF(ISNUMBER('JobPlanner Data'!U12),TEXT('JobPlanner Data'!U12,"YYYY-MM-DD"),"")) | P11: =IF('JobPlanner Data'!O12="","","JobPlanner Data'!O12) | Q11: =IF('JobPlanner Data'!P12="","","JobPlanner Data'!P12)
A12: =IF('JobPlanner Data'!A13="","",IF(ISBLANK('JobPlanner Data'!A13),"",'JobPlanner Data'!A13)) | B12: =IF('JobPlanner Data'!B13="","",LOWER('JobPlanner Data'!B13)) | C12: =IF('JobPlanner Data'!D13<>"","JobPlanner Data'!D13,IF('JobPlanner Data'!F13<>"","JobPlanner Data'!F13,"")) | D12: =IF('JobPlanner Data'!J13="","",LOWER('JobPlanner Data'!J13)) | E12: =IF('JobPlanner Data'!C13="","",IFERROR(VLOOKUP('JobPlanner Data'!C13,'Company Lookup'!A:B,2,FALSE),"[NOT FOUND]")) | F12: =IF('JobPlanner Data'!G13="","",VALUE(SUBSTITUTE(SUBSTITUTE('JobPlanner Data'!G13,"$",""),",",""))) | G12: ="amount" | H12: =IF('JobPlanner Data'!L13="","","JobPlanner Data'!L13) | I12: =IF('JobPlanner Data'!H13="","","JobPlanner Data'!H13) | J12: =IF('JobPlanner Data'!N13="","",IF(ISNUMBER('JobPlanner Data'!N13),TEXT('JobPlanner Data'!N13,"YYYY-MM-DD"),"")) | K12: =IF('JobPlanner Data'!Q13="","",IF(ISNUMBER('JobPlanner Data'!Q13),TEXT('JobPlanner Data'!Q13,"YYYY-MM-DD"),"")) | L12: =IF('JobPlanner Data'!I13<>"",IF(ISNUMBER('JobPlanner Data'!I13),TEXT('JobPlanner Data'!I13,"YYYY-MM-DD"),""),IF('JobPlanner Data'!T13<>"",IF(ISNUMBER('JobPlanner Data'!T13),TEXT('JobPlanner Data'!T13,"YYYY-MM-DD"),""),"")) | M12: =IF('JobPlanner Data'!S13="","",IF(ISNUMBER('JobPlanner Data'!S13),TEXT('JobPlanner Data'!S13,"YYYY-MM-DD"),"")) | N12: =IF('JobPlanner Data'!R13="","",IF(ISNUMBER('JobPlanner Data'!R13),TEXT('JobPlanner Data'!R13,"YYYY-MM-DD"),"")) | O12: =IF('JobPlanner Data'!U13="","",IF(ISNUMBER('JobPlanner Data'!U13),TEXT('JobPlanner Data'!U13,"YYYY-MM-DD"),"")) | P12: =IF('JobPlanner Data'!O13="","","JobPlanner Data'!O13) | Q12: =IF('JobPlanner Data'!P13="","","JobPlanner Data'!P13)
A13: =IF('JobPlanner Data'!A14="","",IF(ISBLANK('JobPlanner Data'!A14),"",'JobPlanner Data'!A14)) | B13: =IF('JobPlanner Data'!B14="","",LOWER('JobPlanner Data'!B14)) | C13: =IF('JobPlanner Data'!D14<>"","JobPlanner Data'!D14,IF('JobPlanner Data'!F14<>"","JobPlanner Data'!F14,"")) | D13: =IF('JobPlanner Data'!J14="","",LOWER('JobPlanner Data'!J14)) | E13: =IF('JobPlanner Data'!C14="","",IFERROR(VLOOKUP('JobPlanner Data'!C14,'Company Lookup'!A:B,2,FALSE),"[NOT FOUND]")) | F13: =IF('JobPlanner Data'!G14="","",VALUE(SUBSTITUTE(SUBSTITUTE('JobPlanner Data'!G14,"$",""),",",""))) | G13: ="amount" | H13: =IF('JobPlanner Data'!L14="","","JobPlanner Data'!L14) | I13: =IF('JobPlanner Data'!H14="","","JobPlanner Data'!H14) | J13: =IF('JobPlanner Data'!N14="","",IF(ISNUMBER('JobPlanner Data'!N14),TEXT('JobPlanner Data'!N14,"YYYY-MM-DD"),"")) | K13: =IF('JobPlanner Data'!Q14="","",IF(ISNUMBER('JobPlanner Data'!Q14),TEXT('JobPlanner Data'!Q14,"YYYY-MM-DD"),"")) | L13: =IF('JobPlanner Data'!I14<>"",IF(ISNUMBER('JobPlanner Data'!I14),TEXT('JobPlanner Data'!I14,"YYYY-MM-DD"),""),IF('JobPlanner Data'!T14<>"",IF(ISNUMBER('JobPlanner Data'!T14),TEXT('JobPlanner Data'!T14,"YYYY-MM-DD"),""),"")) | M13: =IF('JobPlanner Data'!S14="","",IF(ISNUMBER('JobPlanner Data'!S14),TEXT('JobPlanner Data'!S14,"YYYY-MM-DD"),"")) | N13: =IF('JobPlanner Data'!R14="","",IF(ISNUMBER('JobPlanner Data'!R14),TEXT('JobPlanner Data'!R14,"YYYY-MM-DD"),"")) | O13: =IF('JobPlanner Data'!U14="","",IF(ISNUMBER('JobPlanner Data'!U14),TEXT('JobPlanner Data'!U14,"YYYY-MM-DD"),"")) | P13: =IF('JobPlanner Data'!O14="","","JobPlanner Data'!O14) | Q13: =IF('JobPlanner Data'!P14="","","JobPlanner Data'!P14)
A14: =IF('JobPlanner Data'!A15="","",IF(ISBLANK('JobPlanner Data'!A15),"",'JobPlanner Data'!A15)) | B14: =IF('JobPlanner Data'!B15="","",LOWER('JobPlanner Data'!B15)) | C14: =IF('JobPlanner Data'!D15<>"","JobPlanner Data'!D15,IF('JobPlanner Data'!F15<>"","JobPlanner Data'!F15,"")) | D14: =IF('JobPlanner Data'!J15="","",LOWER('JobPlanner Data'!J15)) | E14: =IF('JobPlanner Data'!C15="","",IFERROR(VLOOKUP('JobPlanner Data'!C15,'Company Lookup'!A:B,2,FALSE),"[NOT FOUND]")) | F14: =IF('JobPlanner Data'!G15="","",VALUE(SUBSTITUTE(SUBSTITUTE('JobPlanner Data'!G15,"$",""),",",""))) | G14: ="amount" | H14: =IF('JobPlanner Data'!L15="","","JobPlanner Data'!L15) | I14: =IF('JobPlanner Data'!H15="","","JobPlanner Data'!H15) | J14: =IF('JobPlanner Data'!N15="","",IF(ISNUMBER('JobPlanner Data'!N15),TEXT('JobPlanner Data'!N15,"YYYY-MM-DD"),"")) | K14: =IF('JobPlanner Data'!Q15="","",IF(ISNUMBER('JobPlanner Data'!Q15),TEXT('JobPlanner Data'!Q15,"YYYY-MM-DD"),"")) | L14: =IF('JobPlanner Data'!I15<>"",IF(ISNUMBER('JobPlanner Data'!I15),TEXT('JobPlanner Data'!I15,"YYYY-MM-DD"),""),IF('JobPlanner Data'!T15<>"",IF(ISNUMBER('JobPlanner Data'!T15),TEXT('JobPlanner Data'!T15,"YYYY-MM-DD"),""),"")) | M14: =IF('JobPlanner Data'!S15="","",IF(ISNUMBER('JobPlanner Data'!S15),TEXT('JobPlanner Data'!S15,"YYYY-MM-DD"),"")) | N14: =IF('JobPlanner Data'!R15="","",IF(ISNUMBER('JobPlanner Data'!R15),TEXT('JobPlanner Data'!R15,"YYYY-MM-DD"),"")) | O14: =IF('JobPlanner Data'!U15="","",IF(ISNUMBER('JobPlanner Data'!U15),TEXT('JobPlanner Data'!U15,"YYYY-MM-DD"),"")) | P14: =IF('JobPlanner Data'!O15="","","JobPlanner Data'!O15) | Q14: =IF('JobPlanner Data'!P15="","","JobPlanner Data'!P15)
A15: =IF('JobPlanner Data'!A16="","",IF(ISBLANK('JobPlanner Data'!A16),"",'JobPlanner Data'!A16)) | B15: =IF('JobPlanner Data'!B16="","",LOWER('JobPlanner Data'!B16)) | C15: =IF('JobPlanner Data'!D16<>"","JobPlanner Data'!D16,IF('JobPlanner Data'!F16<>"","JobPlanner Data'!F16,"")) | D15: =IF('JobPlanner Data'!J16="","",LOWER('JobPlanner Data'!J16)) | E15: =IF('JobPlanner Data'!C16="","",IFERROR(VLOOKUP('JobPlanner Data'!C16,'Company Lookup'!A:B,2,FALSE),"[NOT FOUND]")) | F15: =IF('JobPlanner Data'!G16="","",VALUE(SUBSTITUTE(SUBSTITUTE('JobPlanner Data'!G16,"$",""),",",""))) | G15: ="amount" | H15: =IF('JobPlanner Data'!L16="","","JobPlanner Data'!L16) | I15: =IF('JobPlanner Data'!H16="","","JobPlanner Data'!H16) | J15: =IF('JobPlanner Data'!N16="","",IF(ISNUMBER('JobPlanner Data'!N16),TEXT('JobPlanner Data'!N16,"YYYY-MM-DD"),"")) | K15: =IF('JobPlanner Data'!Q16="","",IF(ISNUMBER('JobPlanner Data'!Q16),TEXT('JobPlanner Data'!Q16,"YYYY-MM-DD"),"")) | L15: =IF('JobPlanner Data'!I16<>"",IF(ISNUMBER('JobPlanner Data'!I16),TEXT('JobPlanner Data'!I16,"YYYY-MM-DD"),""),IF('JobPlanner Data'!T16<>"",IF(ISNUMBER('JobPlanner Data'!T16),TEXT('JobPlanner Data'!T16,"YYYY-MM-DD"),""),"")) | M15: =IF('JobPlanner Data'!S16="","",IF(ISNUMBER('JobPlanner Data'!S16),TEXT('JobPlanner Data'!S16,"YYYY-MM-DD"),"")) | N15: =IF('JobPlanner Data'!R16="","",IF(ISNUMBER('JobPlanner Data'!R16),TEXT('JobPlanner Data'!R16,"YYYY-MM-DD"),"")) | O15: =IF('JobPlanner Data'!U16="","",IF(ISNUMBER('JobPlanner Data'!U16),TEXT('JobPlanner Data'!U16,"YYYY-MM-DD"),"")) | P15: =IF('JobPlanner Data'!O16="","","JobPlanner Data'!O16) | Q15: =IF('JobPlanner Data'!P16="","","JobPlanner Data'!P16)
A16: =IF('JobPlanner Data'!A17="","",IF(ISBLANK('JobPlanner Data'!A17),"",'JobPlanner Data'!A17)) | B16: =IF('JobPlanner Data'!B17="","",LOWER('JobPlanner Data'!B17)) | C16: =IF('JobPlanner Data'!D17<>"","JobPlanner Data'!D17,IF('JobPlanner Data'!F17<>"","JobPlanner Data'!F17,"")) | D16: =IF('JobPlanner Data'!J17="","",LOWER('JobPlanner Data'!J17)) | E16: =IF('JobPlanner Data'!C17="","",IFERROR(VLOOKUP('JobPlanner Data'!C17,'Company Lookup'!A:B,2,FALSE),"[NOT FOUND]")) | F16: =IF('JobPlanner Data'!G17="","",VALUE(SUBSTITUTE(SUBSTITUTE('JobPlanner Data'!G17,"$",""),",",""))) | G16: ="amount" | H16: =IF('JobPlanner Data'!L17="","","JobPlanner Data'!L17) | I16: =IF('JobPlanner Data'!H17="","","JobPlanner Data'!H17) | J16: =IF('JobPlanner Data'!N17="","",IF(ISNUMBER('JobPlanner Data'!N17),TEXT('JobPlanner Data'!N17,"YYYY-MM-DD"),"")) | K16: =IF('JobPlanner Data'!Q17="","",IF(ISNUMBER('JobPlanner Data'!Q17),TEXT('JobPlanner Data'!Q17,"YYYY-MM-DD"),"")) | L16: =IF('JobPlanner Data'!I17<>"",IF(ISNUMBER('JobPlanner Data'!I17),TEXT('JobPlanner Data'!I17,"YYYY-MM-DD"),""),IF('JobPlanner Data'!T17<>"",IF(ISNUMBER('JobPlanner Data'!T17),TEXT('JobPlanner Data'!T17,"YYYY-MM-DD"),""),"")) | M16: =IF('JobPlanner Data'!S17="","",IF(ISNUMBER('JobPlanner Data'!S17),TEXT('JobPlanner Data'!S17,"YYYY-MM-DD"),"")) | N16: =IF('JobPlanner Data'!R17="","",IF(ISNUMBER('JobPlanner Data'!R17),TEXT('JobPlanner Data'!R17,"YYYY-MM-DD"),"")) | O16: =IF('JobPlanner Data'!U17="","",IF(ISNUMBER('JobPlanner Data'!U17),TEXT('JobPlanner Data'!U17,"YYYY-MM-DD"),"")) | P16: =IF('JobPlanner Data'!O17="","","JobPlanner Data'!O17) | Q16: =IF('JobPlanner Data'!P17="","","JobPlanner Data'!P17)
A17: =IF('JobPlanner Data'!A18="","",IF(ISBLANK('JobPlanner Data'!A18),"",'JobPlanner Data'!A18)) | B17: =IF('JobPlanner Data'!B18="","",LOWER('JobPlanner Data'!B18)) | C17: =IF('JobPlanner Data'!D18<>"","JobPlanner Data'!D18,IF('JobPlanner Data'!F18<>"","JobPlanner Data'!F18,"")) | D17: =IF('JobPlanner Data'!J18="","",LOWER('JobPlanner Data'!J18)) | E17: =IF('JobPlanner Data'!C18="","",IFERROR(VLOOKUP('JobPlanner Data'!C18,'Company Lookup'!A:B,2,FALSE),"[NOT FOUND]")) | F17: =IF('JobPlanner Data'!G18="","",VALUE(SUBSTITUTE(SUBSTITUTE('JobPlanner Data'!G18,"$",""),",",""))) | G17: ="amount" | H17: =IF('JobPlanner Data'!L18="","","JobPlanner Data'!L18) | I17: =IF('JobPlanner Data'!H18="","","JobPlanner Data'!H18) | J17: =IF('JobPlanner Data'!N18="","",IF(ISNUMBER('JobPlanner Data'!N18),TEXT('JobPlanner Data'!N18,"YYYY-MM-DD"),"")) | K17: =IF('JobPlanner Data'!Q18="","",IF(ISNUMBER('JobPlanner Data'!Q18),TEXT('JobPlanner Data'!Q18,"YYYY-MM-DD"),"")) | L17: =IF('JobPlanner Data'!I18<>"",IF(ISNUMBER('JobPlanner Data'!I18),TEXT('JobPlanner Data'!I18,"YYYY-MM-DD"),""),IF('JobPlanner Data'!T18<>"",IF(ISNUMBER('JobPlanner Data'!T18),TEXT('JobPlanner Data'!T18,"YYYY-MM-DD"),""),"")) | M17: =IF('JobPlanner Data'!S18="","",IF(ISNUMBER('JobPlanner Data'!S18),TEXT('JobPlanner Data'!S18,"YYYY-MM-DD"),"")) | N17: =IF('JobPlanner Data'!R18="","",IF(ISNUMBER('JobPlanner Data'!R18),TEXT('JobPlanner Data'!R18,"YYYY-MM-DD"),"")) | O17: =IF('JobPlanner Data'!U18="","",IF(ISNUMBER('JobPlanner Data'!U18),TEXT('JobPlanner Data'!U18,"YYYY-MM-DD"),"")) | P17: =IF('JobPlanner Data'!O18="","","JobPlanner Data'!O18) | Q17: =IF('JobPlanner Data'!P18="","","JobPlanner Data'!P18)
A18: =IF('JobPlanner Data'!A19="","",IF(ISBLANK('JobPlanner Data'!A19),"",'JobPlanner Data'!A19)) | B18: =IF('JobPlanner Data'!B19="","",LOWER('JobPlanner Data'!B19)) | C18: =IF('JobPlanner Data'!D19<>"","JobPlanner Data'!D19,IF('JobPlanner Data'!F19<>"","JobPlanner Data'!F19,"")) | D18: =IF('JobPlanner Data'!J19="","",LOWER('JobPlanner Data'!J19)) | E18: =IF('JobPlanner Data'!C19="","",IFERROR(VLOOKUP('JobPlanner Data'!C19,'Company Lookup'!A:B,2,FALSE),"[NOT FOUND]")) | F18: =IF('JobPlanner Data'!G19="","",VALUE(SUBSTITUTE(SUBSTITUTE('JobPlanner Data'!G19,"$",""),",",""))) | G18: ="amount" | H18: =IF('JobPlanner Data'!L19="","","JobPlanner Data'!L19) | I18: =IF('JobPlanner Data'!H19="","","JobPlanner Data'!H19) | J18: =IF('JobPlanner Data'!N19="","",IF(ISNUMBER('JobPlanner Data'!N19),TEXT('JobPlanner Data'!N19,"YYYY-MM-DD"),"")) | K18: =IF('JobPlanner Data'!Q19="","",IF(ISNUMBER('JobPlanner Data'!Q19),TEXT('JobPlanner Data'!Q19,"YYYY-MM-DD"),"")) | L18: =IF('JobPlanner Data'!I19<>"",IF(ISNUMBER('JobPlanner Data'!I19),TEXT('JobPlanner Data'!I19,"YYYY-MM-DD"),""),IF('JobPlanner Data'!T19<>"",IF(ISNUMBER('JobPlanner Data'!T19),TEXT('JobPlanner Data'!T19,"YYYY-MM-DD"),""),"")) | M18: =IF('JobPlanner Data'!S19="","",IF(ISNUMBER('JobPlanner Data'!S19),TEXT('JobPlanner Data'!S19,"YYYY-MM-DD"),"")) | N18: =IF('JobPlanner Data'!R19="","",IF(ISNUMBER('JobPlanner Data'!R19),TEXT('JobPlanner Data'!R19,"YYYY-MM-DD"),"")) | O18: =IF('JobPlanner Data'!U19="","",IF(ISNUMBER('JobPlanner Data'!U19),TEXT('JobPlanner Data'!U19,"YYYY-MM-DD"),"")) | P18: =IF('JobPlanner Data'!O19="","","JobPlanner Data'!O19) | Q18: =IF('JobPlanner Data'!P19="","","JobPlanner Data'!P19)
A19: =IF('JobPlanner Data'!A20="","",IF(ISBLANK('JobPlanner Data'!A20),"",'JobPlanner Data'!A20)) | B19: =IF('JobPlanner Data'!B20="","",LOWER('JobPlanner Data'!B20)) | C19: =IF('JobPlanner Data'!D20<>"","JobPlanner Data'!D20,IF('JobPlanner Data'!F20<>"","JobPlanner Data'!F20,"")) | D19: =IF('JobPlanner Data'!J20="","",LOWER('JobPlanner Data'!J20)) | E19: =IF('JobPlanner Data'!C20="","",IFERROR(VLOOKUP('JobPlanner Data'!C20,'Company Lookup'!A:B,2,FALSE),"[NOT FOUND]")) | F19: =IF('JobPlanner Data'!G20="","",VALUE(SUBSTITUTE(SUBSTITUTE('JobPlanner Data'!G20,"$",""),",",""))) | G19: ="amount" | H19: =IF('JobPlanner Data'!L20="","","JobPlanner Data'!L20) | I19: =IF('JobPlanner Data'!H20="","","JobPlanner Data'!H20) | J19: =IF('JobPlanner Data'!N20="","",IF(ISNUMBER('JobPlanner Data'!N20),TEXT('JobPlanner Data'!N20,"YYYY-MM-DD"),"")) | K19: =IF('JobPlanner Data'!Q20="","",IF(ISNUMBER('JobPlanner Data'!Q20),TEXT('JobPlanner Data'!Q20,"YYYY-MM-DD"),"")) | L19: =IF('JobPlanner Data'!I20<>"",IF(ISNUMBER('JobPlanner Data'!I20),TEXT('JobPlanner Data'!I20,"YYYY-MM-DD"),""),IF('JobPlanner Data'!T20<>"",IF(ISNUMBER('JobPlanner Data'!T20),TEXT('JobPlanner Data'!T20,"YYYY-MM-DD"),""),"")) | M19: =IF('JobPlanner Data'!S20="","",IF(ISNUMBER('JobPlanner Data'!S20),TEXT('JobPlanner Data'!S20,"YYYY-MM-DD"),"")) | N19: =IF('JobPlanner Data'!R20="","",IF(ISNUMBER('JobPlanner Data'!R20),TEXT('JobPlanner Data'!R20,"YYYY-MM-DD"),"")) | O19: =IF('JobPlanner Data'!U20="","",IF(ISNUMBER('JobPlanner Data'!U20),TEXT('JobPlanner Data'!U20,"YYYY-MM-DD"),"")) | P19: =IF('JobPlanner Data'!O20="","","JobPlanner Data'!O20) | Q19: =IF('JobPlanner Data'!P20="","","JobPlanner Data'!P20)
A20: =IF('JobPlanner Data'!A21="","",IF(ISBLANK('JobPlanner Data'!A21),"",'JobPlanner Data'!A21)) | B20: =IF('JobPlanner Data'!B21="","",LOWER('JobPlanner Data'!B21)) | C20: =IF('JobPlanner Data'!D21<>"","JobPlanner Data'!D21,IF('JobPlanner Data'!F21<>"","JobPlanner Data'!F21,"")) | D20: =IF('JobPlanner Data'!J21="","",LOWER('JobPlanner Data'!J21)) | E20: =IF('JobPlanner Data'!C21="","",IFERROR(VLOOKUP('JobPlanner Data'!C21,'Company Lookup'!A:B,2,FALSE),"[NOT FOUND]")) | F20: =IF('JobPlanner Data'!G21="","",VALUE(SUBSTITUTE(SUBSTITUTE('JobPlanner Data'!G21,"$",""),",",""))) | G20: ="amount" | H20: =IF('JobPlanner Data'!L21="","","JobPlanner Data'!L21) | I20: =IF('JobPlanner Data'!H21="","","JobPlanner Data'!H21) | J20: =IF('JobPlanner Data'!N21="","",IF(ISNUMBER('JobPlanner Data'!N21),TEXT('JobPlanner Data'!N21,"YYYY-MM-DD"),"")) | K20: =IF('JobPlanner Data'!Q21="","",IF(ISNUMBER('JobPlanner Data'!Q21),TEXT('JobPlanner Data'!Q21,"YYYY-MM-DD"),"")) | L20: =IF('JobPlanner Data'!I21<>"",IF(ISNUMBER('JobPlanner Data'!I21),TEXT('JobPlanner Data'!I21,"YYYY-MM-DD"),""),IF('JobPlanner Data'!T21<>"",IF(ISNUMBER('JobPlanner Data'!T21),TEXT('JobPlanner Data'!T21,"YYYY-MM-DD"),""),"")) | M20: =IF('JobPlanner Data'!S21="","",IF(ISNUMBER('JobPlanner Data'!S21),TEXT('JobPlanner Data'!S21,"YYYY-MM-DD"),"")) | N20: =IF('JobPlanner Data'!R21="","",IF(ISNUMBER('JobPlanner Data'!R21),TEXT('JobPlanner Data'!R21,"YYYY-MM-DD"),"")) | O20: =IF('JobPlanner Data'!U21="","",IF(ISNUMBER('JobPlanner Data'!U21),TEXT('JobPlanner Data'!U21,"YYYY-MM-DD"),"")) | P20: =IF('JobPlanner Data'!O21="","","JobPlanner Data'!O21) | Q20: =IF('JobPlanner Data'!P21="","","JobPlanner Data'!P21)
A21: =IF('JobPlanner Data'!A22="","",IF(ISBLANK('JobPlanner Data'!A22),"",'JobPlanner Data'!A22)) | B21: =IF('JobPlanner Data'!B22="","",LOWER('JobPlanner Data'!B22)) | C21: =IF('JobPlanner Data'!D22<>"","JobPlanner Data'!D22,IF('JobPlanner Data'!F22<>"","JobPlanner Data'!F22,"")) | D21: =IF('JobPlanner Data'!J22="","",LOWER('JobPlanner Data'!J22)) | E21: =IF('JobPlanner Data'!C22="","",IFERROR(VLOOKUP('JobPlanner Data'!C22,'Company Lookup'!A:B,2,FALSE),"[NOT FOUND]")) | F21: =IF('JobPlanner Data'!G22="","",VALUE(SUBSTITUTE(SUBSTITUTE('JobPlanner Data'!G22,"$",""),",",""))) | G21: ="amount" | H21: =IF('JobPlanner Data'!L22="","","JobPlanner Data'!L22) | I21: =IF('JobPlanner Data'!H22="","","JobPlanner Data'!H22) | J21: =IF('JobPlanner Data'!N22="","",IF(ISNUMBER('JobPlanner Data'!N22),TEXT('JobPlanner Data'!N22,"YYYY-MM-DD"),"")) | K21: =IF('JobPlanner Data'!Q22="","",IF(ISNUMBER('JobPlanner Data'!Q22),TEXT('JobPlanner Data'!Q22,"YYYY-MM-DD"),"")) | L21: =IF('JobPlanner Data'!I22<>"",IF(ISNUMBER('JobPlanner Data'!I22),TEXT('JobPlanner Data'!I22,"YYYY-MM-DD"),""),IF('JobPlanner Data'!T22<>"",IF(ISNUMBER('JobPlanner Data'!T22),TEXT('JobPlanner Data'!T22,"YYYY-MM-DD"),""),"")) | M21: =IF('JobPlanner Data'!S22="","",IF(ISNUMBER('JobPlanner Data'!S22),TEXT('JobPlanner Data'!S22,"YYYY-MM-DD"),"")) | N21: =IF('JobPlanner Data'!R22="","",IF(ISNUMBER('JobPlanner Data'!R22),TEXT('JobPlanner Data'!R22,"YYYY-MM-DD"),"")) | O21: =IF('JobPlanner Data'!U22="","",IF(ISNUMBER('JobPlanner Data'!U22),TEXT('JobPlanner Data'!U22,"YYYY-MM-DD"),"")) | P21: =IF('JobPlanner Data'!O22="","","JobPlanner Data'!O22) | Q21: =IF('JobPlanner Data'!P22="","","JobPlanner Data'!P22)
A22: =IF('JobPlanner Data'!A23="","",IF(ISBLANK('JobPlanner Data'!A23),"",'JobPlanner Data'!A23)) | B22: =IF('JobPlanner Data'!B23="","",LOWER('JobPlanner Data'!B23)) | C22: =IF('JobPlanner Data'!D23<>"","JobPlanner Data'!D23,IF('JobPlanner Data'!F23<>"","JobPlanner Data'!F23,"")) | D22: =IF('JobPlanner Data'!J23="","",LOWER('JobPlanner Data'!J23)) | E22: =IF('JobPlanner Data'!C23="","",IFERROR(VLOOKUP('JobPlanner Data'!C23,'Company Lookup'!A:B,2,FALSE),"[NOT FOUND]")) | F22: =IF('JobPlanner Data'!G23="","",VALUE(SUBSTITUTE(SUBSTITUTE('JobPlanner Data'!G23,"$",""),",",""))) | G22: ="amount" | H22: =IF('JobPlanner Data'!L23="","","JobPlanner Data'!L23) | I22: =IF('JobPlanner Data'!H23="","","JobPlanner Data'!H23) | J22: =IF('JobPlanner Data'!N23="","",IF(ISNUMBER('JobPlanner Data'!N23),TEXT('JobPlanner Data'!N23,"YYYY-MM-DD"),"")) | K22: =IF('JobPlanner Data'!Q23="","",IF(ISNUMBER('JobPlanner Data'!Q23),TEXT('JobPlanner Data'!Q23,"YYYY-MM-DD"),"")) | L22: =IF('JobPlanner Data'!I23<>"",IF(ISNUMBER('JobPlanner Data'!I23),TEXT('JobPlanner Data'!I23,"YYYY-MM-DD"),""),IF('JobPlanner Data'!T23<>"",IF(ISNUMBER('JobPlanner Data'!T23),TEXT('JobPlanner Data'!T23,"YYYY-MM-DD"),""),"")) | M22: =IF('JobPlanner Data'!S23="","",IF(ISNUMBER('JobPlanner Data'!S23),TEXT('JobPlanner Data'!S23,"YYYY-MM-DD"),"")) | N22: =IF('JobPlanner Data'!R23="","",IF(ISNUMBER('JobPlanner Data'!R23),TEXT('JobPlanner Data'!R23,"YYYY-MM-DD"),"")) | O22: =IF('JobPlanner Data'!U23="","",IF(ISNUMBER('JobPlanner Data'!U23),TEXT('JobPlanner Data'!U23,"YYYY-MM-DD"),"")) | P22: =IF('JobPlanner Data'!O23="","","JobPlanner Data'!O23) | Q22: =IF('JobPlanner Data'!P23="","","JobPlanner Data'!P23)
A23: =IF('JobPlanner Data'!A24="","",IF(ISBLANK('JobPlanner Data'!A24),"",'JobPlanner Data'!A24)) | B23: =IF('JobPlanner Data'!B24="","",LOWER('JobPlanner Data'!B24)) | C23: =IF('JobPlanner Data'!D24<>"","JobPlanner Data'!D24,IF('JobPlanner Data'!F24<>"","JobPlanner Data'!F24,"")) | D23: =IF('JobPlanner Data'!J24="","",LOWER('JobPlanner Data'!J24)) | E23: =IF('JobPlanner Data'!C24="","",IFERROR(VLOOKUP('JobPlanner Data'!C24,'Company Lookup'!A:B,2,FALSE),"[NOT FOUND]")) | F23: =IF('JobPlanner Data'!G24="","",VALUE(SUBSTITUTE(SUBSTITUTE('JobPlanner Data'!G24,"$",""),",",""))) | G23: ="amount" | H23: =IF('JobPlanner Data'!L24="","","JobPlanner Data'!L24) | I23: =IF('JobPlanner Data'!H24="","","JobPlanner Data'!H24) | J23: =IF('JobPlanner Data'!N24="","",IF(ISNUMBER('JobPlanner Data'!N24),TEXT('JobPlanner Data'!N24,"YYYY-MM-DD"),"")) | K23: =IF('JobPlanner Data'!Q24="","",IF(ISNUMBER('JobPlanner Data'!Q24),TEXT('JobPlanner Data'!Q24,"YYYY-MM-DD"),"")) | L23: =IF('JobPlanner Data'!I24<>"",IF(ISNUMBER('JobPlanner Data'!I24),TEXT('JobPlanner Data'!I24,"YYYY-MM-DD"),""),IF('JobPlanner Data'!T24<>"",IF(ISNUMBER('JobPlanner Data'!T24),TEXT('JobPlanner Data'!T24,"YYYY-MM-DD"),""),"")) | M23: =IF('JobPlanner Data'!S24="","",IF(ISNUMBER('JobPlanner Data'!S24),TEXT('JobPlanner Data'!S24,"YYYY-MM-DD"),"")) | N23: =IF('JobPlanner Data'!R24="","",IF(ISNUMBER('JobPlanner Data'!R24),TEXT('JobPlanner Data'!R24,"YYYY-MM-DD"),"")) | O23: =IF('JobPlanner Data'!U24="","",IF(ISNUMBER('JobPlanner Data'!U24),TEXT('JobPlanner Data'!U24,"YYYY-MM-DD"),"")) | P23: =IF('JobPlanner Data'!O24="","","JobPlanner Data'!O24) | Q23: =IF('JobPlanner Data'!P24="","","JobPlanner Data'!P24)
A24: =IF('JobPlanner Data'!A25="","",IF(ISBLANK('JobPlanner Data'!A25),"",'JobPlanner Data'!A25)) | B24: =IF('JobPlanner Data'!B25="","",LOWER('JobPlanner Data'!B25)) | C24: =IF('JobPlanner Data'!D25<>"","JobPlanner Data'!D25,IF('JobPlanner Data'!F25<>"","JobPlanner Data'!F25,"")) | D24: =IF('JobPlanner Data'!J25="","",LOWER('JobPlanner Data'!J25)) | E24: =IF('JobPlanner Data'!C25="","",IFERROR(VLOOKUP('JobPlanner Data'!C25,'Company Lookup'!A:B,2,FALSE),"[NOT FOUND]")) | F24: =IF('JobPlanner Data'!G25="","",VALUE(SUBSTITUTE(SUBSTITUTE('JobPlanner Data'!G25,"$",""),",",""))) | G24: ="amount" | H24: =IF('JobPlanner Data'!L25="","","JobPlanner Data'!L25) | I24: =IF('JobPlanner Data'!H25="","","JobPlanner Data'!H25) | J24: =IF('JobPlanner Data'!N25="","",IF(ISNUMBER('JobPlanner Data'!N25),TEXT('JobPlanner Data'!N25,"YYYY-MM-DD"),"")) | K24: =IF('JobPlanner Data'!Q25="","",IF(ISNUMBER('JobPlanner Data'!Q25),TEXT('JobPlanner Data'!Q25,"YYYY-MM-DD"),"")) | L24: =IF('JobPlanner Data'!I25<>"",IF(ISNUMBER('JobPlanner Data'!I25),TEXT('JobPlanner Data'!I25,"YYYY-MM-DD"),""),IF('JobPlanner Data'!T25<>"",IF(ISNUMBER('JobPlanner Data'!T25),TEXT('JobPlanner Data'!T25,"YYYY-MM-DD"),""),"")) | M24: =IF('JobPlanner Data'!S25="","",IF(ISNUMBER('JobPlanner Data'!S25),TEXT('JobPlanner Data'!S25,"YYYY-MM-DD"),"")) | N24: =IF('JobPlanner Data'!R25="","",IF(ISNUMBER('JobPlanner Data'!R25),TEXT('JobPlanner Data'!R25,"YYYY-MM-DD"),"")) | O24: =IF('JobPlanner Data'!U25="","",IF(ISNUMBER('JobPlanner Data'!U25),TEXT('JobPlanner Data'!U25,"YYYY-MM-DD"),"")) | P24: =IF('JobPlanner Data'!O25="","","JobPlanner Data'!O25) | Q24: =IF('JobPlanner Data'!P25="","","JobPlanner Data'!P25)
A25: =IF('JobPlanner Data'!A26="","",IF(ISBLANK('JobPlanner Data'!A26),"",'JobPlanner Data'!A26)) | B25: =IF('JobPlanner Data'!B26="","",LOWER('JobPlanner Data'!B26)) | C25: =IF('JobPlanner Data'!D26<>"","JobPlanner Data'!D26,IF('JobPlanner Data'!F26<>"","JobPlanner Data'!F26,"")) | D25: =IF('JobPlanner Data'!J26="","",LOWER('JobPlanner Data'!J26)) | E25: =IF('JobPlanner Data'!C26="","",IFERROR(VLOOKUP('JobPlanner Data'!C26,'Company Lookup'!A:B,2,FALSE),"[NOT FOUND]")) | F25: =IF('JobPlanner Data'!G26="","",VALUE(SUBSTITUTE(SUBSTITUTE('JobPlanner Data'!G26,"$",""),",",""))) | G25: ="amount" | H25: =IF('JobPlanner Data'!L26="","","JobPlanner Data'!L26) | I25: =IF('JobPlanner Data'!H26="","","JobPlanner Data'!H26) | J25: =IF('JobPlanner Data'!N26="","",IF(ISNUMBER('JobPlanner Data'!N26),TEXT('JobPlanner Data'!N26,"YYYY-MM-DD"),"")) | K25: =IF('JobPlanner Data'!Q26="","",IF(ISNUMBER('JobPlanner Data'!Q26),TEXT('JobPlanner Data'!Q26,"YYYY-MM-DD"),"")) | L25: =IF('JobPlanner Data'!I26<>"",IF(ISNUMBER('JobPlanner Data'!I26),TEXT('JobPlanner Data'!I26,"YYYY-MM-DD"),""),IF('JobPlanner Data'!T26<>"",IF(ISNUMBER('JobPlanner Data'!T26),TEXT('JobPlanner Data'!T26,"YYYY-MM-DD"),""),"")) | M25: =IF('JobPlanner Data'!S26="","",IF(ISNUMBER('JobPlanner Data'!S26),TEXT('JobPlanner Data'!S26,"YYYY-MM-DD"),"")) | N25: =IF('JobPlanner Data'!R26="","",IF(ISNUMBER('JobPlanner Data'!R26),TEXT('JobPlanner Data'!R26,"YYYY-MM-DD"),"")) | O25: =IF('JobPlanner Data'!U26="","",IF(ISNUMBER('JobPlanner Data'!U26),TEXT('JobPlanner Data'!U26,"YYYY-MM-DD"),"")) | P25: =IF('JobPlanner Data'!O26="","","JobPlanner Data'!O26) | Q25: =IF('JobPlanner Data'!P26="","","JobPlanner Data'!P26)
A26: =IF('JobPlanner Data'!A27="","",IF(ISBLANK('JobPlanner Data'!A27),"",'JobPlanner Data'!A27)) | B26: =IF('JobPlanner Data'!B27="","",LOWER('JobPlanner Data'!B27)) | C26: =IF('JobPlanner Data'!D27<>"","JobPlanner Data'!D27,IF('JobPlanner Data'!F27<>"","JobPlanner Data'!F27,"")) | D26: =IF('JobPlanner Data'!J27="","",LOWER('JobPlanner Data'!J27)) | E26: =IF('JobPlanner Data'!C27="","",IFERROR(VLOOKUP('JobPlanner Data'!C27,'Company Lookup'!A:B,2,FALSE),"[NOT FOUND]")) | F26: =IF('JobPlanner Data'!G27="","",VALUE(SUBSTITUTE(SUBSTITUTE('JobPlanner Data'!G27,"$",""),",",""))) | G26: ="amount" | H26: =IF('JobPlanner Data'!L27="","","JobPlanner Data'!L27) | I26: =IF('JobPlanner Data'!H27="","","JobPlanner Data'!H27) | J26: =IF('JobPlanner Data'!N27="","",IF(ISNUMBER('JobPlanner Data'!N27),TEXT('JobPlanner Data'!N27,"YYYY-MM-DD"),"")) | K26: =IF('JobPlanner Data'!Q27="","",IF(ISNUMBER('JobPlanner Data'!Q27),TEXT('JobPlanner Data'!Q27,"YYYY-MM-DD"),"")) | L26: =IF('JobPlanner Data'!I27<>"",IF(ISNUMBER('JobPlanner Data'!I27),TEXT('JobPlanner Data'!I27,"YYYY-MM-DD"),""),IF('JobPlanner Data'!T27<>"",IF(ISNUMBER('JobPlanner Data'!T27),TEXT('JobPlanner Data'!T27,"YYYY-MM-DD"),""),"")) | M26: =IF('JobPlanner Data'!S27="","",IF(ISNUMBER('JobPlanner Data'!S27),TEXT('JobPlanner Data'!S27,"YYYY-MM-DD"),"")) | N26: =IF('JobPlanner Data'!R27="","",IF(ISNUMBER('JobPlanner Data'!R27),TEXT('JobPlanner Data'!R27,"YYYY-MM-DD"),"")) | O26: =IF('JobPlanner Data'!U27="","",IF(ISNUMBER('JobPlanner Data'!U27),TEXT('JobPlanner Data'!U27,"YYYY-MM-DD"),"")) | P26: =IF('JobPlanner Data'!O27="","","JobPlanner Data'!O27) | Q26: =IF('JobPlanner Data'!P27="","","JobPlanner Data'!P27)
A27: =IF('JobPlanner Data'!A28="","",IF(ISBLANK('JobPlanner Data'!A28),"",'JobPlanner Data'!A28)) | B27: =IF('JobPlanner Data'!B28="","",LOWER('JobPlanner Data'!B28)) | C27: =IF('JobPlanner Data'!D28<>"","JobPlanner Data'!D28,IF('JobPlanner Data'!F28<>"","JobPlanner Data'!F28,"")) | D27: =IF('JobPlanner Data'!J28="","",LOWER('JobPlanner Data'!J28)) | E27: =IF('JobPlanner Data'!C28="","",IFERROR(VLOOKUP('JobPlanner Data'!C28,'Company Lookup'!A:B,2,FALSE),"[NOT FOUND]")) | F27: =IF('JobPlanner Data'!G28="","",VALUE(SUBSTITUTE(SUBSTITUTE('JobPlanner Data'!G28,"$",""),",",""))) | G27: ="amount" | H27: =IF('JobPlanner Data'!L28="","","JobPlanner Data'!L28) | I27: =IF('JobPlanner Data'!H28="","","JobPlanner Data'!H28) | J27: =IF('JobPlanner Data'!N28="","",IF(ISNUMBER('JobPlanner Data'!N28),TEXT('JobPlanner Data'!N28,"YYYY-MM-DD"),"")) | K27: =IF('JobPlanner Data'!Q28="","",IF(ISNUMBER('JobPlanner Data'!Q28),TEXT('JobPlanner Data'!Q28,"YYYY-MM-DD"),"")) | L27: =IF('JobPlanner Data'!I28<>"",IF(ISNUMBER('JobPlanner Data'!I28),TEXT('JobPlanner Data'!I28,"YYYY-MM-DD"),""),IF('JobPlanner Data'!T28<>"",IF(ISNUMBER('JobPlanner Data'!T28),TEXT('JobPlanner Data'!T28,"YYYY-MM-DD"),""),"")) | M27: =IF('JobPlanner Data'!S28="","",IF(ISNUMBER('JobPlanner Data'!S28),TEXT('JobPlanner Data'!S28,"YYYY-MM-DD"),"")) | N27: =IF('JobPlanner Data'!R28="","",IF(ISNUMBER('JobPlanner Data'!R28),TEXT('JobPlanner Data'!R28,"YYYY-MM-DD"),"")) | O27: =IF('JobPlanner Data'!U28="","",IF(ISNUMBER('JobPlanner Data'!U28),TEXT('JobPlanner Data'!U28,"YYYY-MM-DD"),"")) | P27: =IF('JobPlanner Data'!O28="","","JobPlanner Data'!O28) | Q27: =IF('JobPlanner Data'!P28="","","JobPlanner Data'!P28)
A28: =IF('JobPlanner Data'!A29="","",IF(ISBLANK('JobPlanner Data'!A29),"",'JobPlanner Data'!A29)) | B28: =IF('JobPlanner Data'!B29="","",LOWER('JobPlanner Data'!B29)) | C28: =IF('JobPlanner Data'!D29<>"","JobPlanner Data'!D29,IF('JobPlanner Data'!F29<>"","JobPlanner Data'!F29,"")) | D28: =IF('JobPlanner Data'!J29="","",LOWER('JobPlanner Data'!J29)) | E28: =IF('JobPlanner Data'!C29="","",IFERROR(VLOOKUP('JobPlanner Data'!C29,'Company Lookup'!A:B,2,FALSE),"[NOT FOUND]")) | F28: =IF('JobPlanner Data'!G29="","",VALUE(SUBSTITUTE(SUBSTITUTE('JobPlanner Data'!G29,"$",""),",",""))) | G28: ="amount" | H28: =IF('JobPlanner Data'!L29="","","JobPlanner Data'!L29) | I28: =IF('JobPlanner Data'!H29="","","JobPlanner Data'!H29) | J28: =IF('JobPlanner Data'!N29="","",IF(ISNUMBER('JobPlanner Data'!N29),TEXT('JobPlanner Data'!N29,"YYYY-MM-DD"),"")) | K28: =IF('JobPlanner Data'!Q29="","",IF(ISNUMBER('JobPlanner Data'!Q29),TEXT('JobPlanner Data'!Q29,"YYYY-MM-DD"),"")) | L28: =IF('JobPlanner Data'!I29<>"",IF(ISNUMBER('JobPlanner Data'!I29),TEXT('JobPlanner Data'!I29,"YYYY-MM-DD"),""),IF('JobPlanner Data'!T29<>"",IF(ISNUMBER('JobPlanner Data'!T29),TEXT('JobPlanner Data'!T29,"YYYY-MM-DD"),""),"")) | M28: =IF('JobPlanner Data'!S29="","",IF(ISNUMBER('JobPlanner Data'!S29),TEXT('JobPlanner Data'!S29,"YYYY-MM-DD"),"")) | N28: =IF('JobPlanner Data'!R29="","",IF(ISNUMBER('JobPlanner Data'!R29),TEXT('JobPlanner Data'!R29,"YYYY-MM-DD"),"")) | O28: =IF('JobPlanner Data'!U29="","",IF(ISNUMBER('JobPlanner Data'!U29),TEXT('JobPlanner Data'!U29,"YYYY-MM-DD"),"")) | P28: =IF('JobPlanner Data'!O29="","","JobPlanner Data'!O29) | Q28: =IF('JobPlanner Data'!P29="","","JobPlanner Data'!P29)
A29: =IF('JobPlanner Data'!A30="","",IF(ISBLANK('JobPlanner Data'!A30),"",'JobPlanner Data'!A30)) | B29: =IF('JobPlanner Data'!B30="","",LOWER('JobPlanner Data'!B30)) | C29: =IF('JobPlanner Data'!D30<>"","JobPlanner Data'!D30,IF('JobPlanner Data'!F30<>"","JobPlanner Data'!F30,"")) | D29: =IF('JobPlanner Data'!J30="","",LOWER('JobPlanner Data'!J30)) | E29: =IF('JobPlanner Data'!C30="","",IFERROR(VLOOKUP('JobPlanner Data'!C30,'Company Lookup'!A:B,2,FALSE),"[NOT FOUND]")) | F29: =IF('JobPlanner Data'!G30="","",VALUE(SUBSTITUTE(SUBSTITUTE('JobPlanner Data'!G30,"$",""),",",""))) | G29: ="amount" | H29: =IF('JobPlanner Data'!L30="","","JobPlanner Data'!L30) | I29: =IF('JobPlanner Data'!H30="","","JobPlanner Data'!H30) | J29: =IF('JobPlanner Data'!N30="","",IF(ISNUMBER('JobPlanner Data'!N30),TEXT('JobPlanner Data'!N30,"YYYY-MM-DD"),"")) | K29: =IF('JobPlanner Data'!Q30="","",IF(ISNUMBER('JobPlanner Data'!Q30),TEXT('JobPlanner Data'!Q30,"YYYY-MM-DD"),"")) | L29: =IF('JobPlanner Data'!I30<>"",IF(ISNUMBER('JobPlanner Data'!I30),TEXT('JobPlanner Data'!I30,"YYYY-MM-DD"),""),IF('JobPlanner Data'!T30<>"",IF(ISNUMBER('JobPlanner Data'!T30),TEXT('JobPlanner Data'!T30,"YYYY-MM-DD"),""),"")) | M29: =IF('JobPlanner Data'!S30="","",IF(ISNUMBER('JobPlanner Data'!S30),TEXT('JobPlanner Data'!S30,"YYYY-MM-DD"),"")) | N29: =IF('JobPlanner Data'!R30="","",IF(ISNUMBER('JobPlanner Data'!R30),TEXT('JobPlanner Data'!R30,"YYYY-MM-DD"),"")) | O29: =IF('JobPlanner Data'!U30="","",IF(ISNUMBER('JobPlanner Data'!U30),TEXT('JobPlanner Data'!U30,"YYYY-MM-DD"),"")) | P29: =IF('JobPlanner Data'!O30="","","JobPlanner Data'!O30) | Q29: =IF('JobPlanner Data'!P30="","","JobPlanner Data'!P30)
A30: =IF('JobPlanner Data'!A31="","",IF(ISBLANK('JobPlanner Data'!A31),"",'JobPlanner Data'!A31)) | B30: =IF('JobPlanner Data'!B31="","",LOWER('JobPlanner Data'!B31)) | C30: =IF('JobPlanner Data'!D31<>"","JobPlanner Data'!D31,IF('JobPlanner Data'!F31<>"","JobPlanner Data'!F31,"")) | D30: =IF('JobPlanner Data'!J31="","",LOWER('JobPlanner Data'!J31)) | E30: =IF('JobPlanner Data'!C31="","",IFERROR(VLOOKUP('JobPlanner Data'!C31,'Company Lookup'!A:B,2,FALSE),"[NOT FOUND]")) | F30: =IF('JobPlanner Data'!G31="","",VALUE(SUBSTITUTE(SUBSTITUTE('JobPlanner Data'!G31,"$",""),",",""))) | G30: ="amount" | H30: =IF('JobPlanner Data'!L31="","","JobPlanner Data'!L31) | I30: =IF('JobPlanner Data'!H31="","","JobPlanner Data'!H31) | J30: =IF('JobPlanner Data'!N31="","",IF(ISNUMBER('JobPlanner Data'!N31),TEXT('JobPlanner Data'!N31,"YYYY-MM-DD"),"")) | K30: =IF('JobPlanner Data'!Q31="","",IF(ISNUMBER('JobPlanner Data'!Q31),TEXT('JobPlanner Data'!Q31,"YYYY-MM-DD"),"")) | L30: =IF('JobPlanner Data'!I31<>"",IF(ISNUMBER('JobPlanner Data'!I31),TEXT('JobPlanner Data'!I31,"YYYY-MM-DD"),""),IF('JobPlanner Data'!T31<>"",IF(ISNUMBER('JobPlanner Data'!T31),TEXT('JobPlanner Data'!T31,"YYYY-MM-DD"),""),"")) | M30: =IF('JobPlanner Data'!S31="","",IF(ISNUMBER('JobPlanner Data'!S31),TEXT('JobPlanner Data'!S31,"YYYY-MM-DD"),"")) | N30: =IF('JobPlanner Data'!R31="","",IF(ISNUMBER('JobPlanner Data'!R31),TEXT('JobPlanner Data'!R31,"YYYY-MM-DD"),"")) | O30: =IF('JobPlanner Data'!U31="","",IF(ISNUMBER('JobPlanner Data'!U31),TEXT('JobPlanner Data'!U31,"YYYY-MM-DD"),"")) | P30: =IF('JobPlanner Data'!O31="","","JobPlanner Data'!O31) | Q30: =IF('JobPlanner Data'!P31="","","JobPlanner Data'!P31)
A31: =IF('JobPlanner Data'!A32="","",IF(ISBLANK('JobPlanner Data'!A32),"",'JobPlanner Data'!A32)) | B31: =IF('JobPlanner Data'!B32="","",LOWER('JobPlanner Data'!B32)) | C31: =IF('JobPlanner Data'!D32<>"","JobPlanner Data'!D32,IF('JobPlanner Data'!F32<>"","JobPlanner Data'!F32,"")) | D31: =IF('JobPlanner Data'!J32="","",LOWER('JobPlanner Data'!J32)) | E31: =IF('JobPlanner Data'!C32="","",IFERROR(VLOOKUP('JobPlanner Data'!C32,'Company Lookup'!A:B,2,FALSE),"[NOT FOUND]")) | F31: =IF('JobPlanner Data'!G32="","",VALUE(SUBSTITUTE(SUBSTITUTE('JobPlanner Data'!G32,"$",""),",",""))) | G31: ="amount" | H31: =IF('JobPlanner Data'!L32="","","JobPlanner Data'!L32) | I31: =IF('JobPlanner Data'!H32="","","JobPlanner Data'!H32) | J31: =IF('JobPlanner Data'!N32="","",IF(ISNUMBER('JobPlanner Data'!N32),TEXT('JobPlanner Data'!N32,"YYYY-MM-DD"),"")) | K31: =IF('JobPlanner Data'!Q32="","",IF(ISNUMBER('JobPlanner Data'!Q32),TEXT('JobPlanner Data'!Q32,"YYYY-MM-DD"),"")) | L31: =IF('JobPlanner Data'!I32<>"",IF(ISNUMBER('JobPlanner Data'!I32),TEXT('JobPlanner Data'!I32,"YYYY-MM-DD"),""),IF('JobPlanner Data'!T32<>"",IF(ISNUMBER('JobPlanner Data'!T32),TEXT('JobPlanner Data'!T32,"YYYY-MM-DD"),""),"")) | M31: =IF('JobPlanner Data'!S32="","",IF(ISNUMBER('JobPlanner Data'!S32),TEXT('JobPlanner Data'!S32,"YYYY-MM-DD"),"")) | N31: =IF('JobPlanner Data'!R32="","",IF(ISNUMBER('JobPlanner Data'!R32),TEXT('JobPlanner Data'!R32,"YYYY-MM-DD"),"")) | O31: =IF('JobPlanner Data'!U32="","",IF(ISNUMBER('JobPlanner Data'!U32),TEXT('JobPlanner Data'!U32,"YYYY-MM-DD"),"")) | P31: =IF('JobPlanner Data'!O32="","","JobPlanner Data'!O32) | Q31: =IF('JobPlanner Data'!P32="","","JobPlanner Data'!P32)
A32: =IF('JobPlanner Data'!A33="","",IF(ISBLANK('JobPlanner Data'!A33),"",'JobPlanner Data'!A33)) | B32: =IF('JobPlanner Data'!B33="","",LOWER('JobPlanner Data'!B33)) | C32: =IF('JobPlanner Data'!D33<>"","JobPlanner Data'!D33,IF('JobPlanner Data'!F33<>"","JobPlanner Data'!F33,"")) | D32: =IF('JobPlanner Data'!J33="","",LOWER('JobPlanner Data'!J33)) | E32: =IF('JobPlanner Data'!C33="","",IFERROR(VLOOKUP('JobPlanner Data'!C33,'Company Lookup'!A:B,2,FALSE),"[NOT FOUND]")) | F32: =IF('JobPlanner Data'!G33="","",VALUE(SUBSTITUTE(SUBSTITUTE('JobPlanner Data'!G33,"$",""),",",""))) | G32: ="amount" | H32: =IF('JobPlanner Data'!L33="","","JobPlanner Data'!L33) | I32: =IF('JobPlanner Data'!H33="","","JobPlanner Data'!H33) | J32: =IF('JobPlanner Data'!N33="","",IF(ISNUMBER('JobPlanner Data'!N33),TEXT('JobPlanner Data'!N33,"YYYY-MM-DD"),"")) | K32: =IF('JobPlanner Data'!Q33="","",IF(ISNUMBER('JobPlanner Data'!Q33),TEXT('JobPlanner Data'!Q33,"YYYY-MM-DD"),"")) | L32: =IF('JobPlanner Data'!I33<>"",IF(ISNUMBER('JobPlanner Data'!I33),TEXT('JobPlanner Data'!I33,"YYYY-MM-DD"),""),IF('JobPlanner Data'!T33<>"",IF(ISNUMBER('JobPlanner Data'!T33),TEXT('JobPlanner Data'!T33,"YYYY-MM-DD"),""),"")) | M32: =IF('JobPlanner Data'!S33="","",IF(ISNUMBER('JobPlanner Data'!S33),TEXT('JobPlanner Data'!S33,"YYYY-MM-DD"),"")) | N32: =IF('JobPlanner Data'!R33="","",IF(ISNUMBER('JobPlanner Data'!R33),TEXT('JobPlanner Data'!R33,"YYYY-MM-DD"),"")) | O32: =IF('JobPlanner Data'!U33="","",IF(ISNUMBER('JobPlanner Data'!U33),TEXT('JobPlanner Data'!U33,"YYYY-MM-DD"),"")) | P32: =IF('JobPlanner Data'!O33="","","JobPlanner Data'!O33) | Q32: =IF('JobPlanner Data'!P33="","","JobPlanner Data'!P33)
A33: =IF('JobPlanner Data'!A34="","",IF(ISBLANK('JobPlanner Data'!A34),"",'JobPlanner Data'!A34)) | B33: =IF('JobPlanner Data'!B34="","",LOWER('JobPlanner Data'!B34)) | C33: =IF('JobPlanner Data'!D34<>"","JobPlanner Data'!D34,IF('JobPlanner Data'!F34<>"","JobPlanner Data'!F34,"")) | D33: =IF('JobPlanner Data'!J34="","",LOWER('JobPlanner Data'!J34)) | E33: =IF('JobPlanner Data'!C34="","",IFERROR(VLOOKUP('JobPlanner Data'!C34,'Company Lookup'!A:B,2,FALSE),"[NOT FOUND]")) | F33: =IF('JobPlanner Data'!G34="","",VALUE(SUBSTITUTE(SUBSTITUTE('JobPlanner Data'!G34,"$",""),",",""))) | G33: ="amount" | H33: =IF('JobPlanner Data'!L34="","","JobPlanner Data'!L34) | I33: =IF('JobPlanner Data'!H34="","","JobPlanner Data'!H34) | J33: =IF('JobPlanner Data'!N34="","",IF(ISNUMBER('JobPlanner Data'!N34),TEXT('JobPlanner Data'!N34,"YYYY-MM-DD"),"")) | K33: =IF('JobPlanner Data'!Q34="","",IF(ISNUMBER('JobPlanner Data'!Q34),TEXT('JobPlanner Data'!Q34,"YYYY-MM-DD"),"")) | L33: =IF('JobPlanner Data'!I34<>"",IF(ISNUMBER('JobPlanner Data'!I34),TEXT('JobPlanner Data'!I34,"YYYY-MM-DD"),""),IF('JobPlanner Data'!T34<>"",IF(ISNUMBER('JobPlanner Data'!T34),TEXT('JobPlanner Data'!T34,"YYYY-MM-DD"),""),"")) | M33: =IF('JobPlanner Data'!S34="","",IF(ISNUMBER('JobPlanner Data'!S34),TEXT('JobPlanner Data'!S34,"YYYY-MM-DD"),"")) | N33: =IF('JobPlanner Data'!R34="","",IF(ISNUMBER('JobPlanner Data'!R34),TEXT('JobPlanner Data'!R34,"YYYY-MM-DD"),"")) | O33: =IF('JobPlanner Data'!U34="","",IF(ISNUMBER('JobPlanner Data'!U34),TEXT('JobPlanner Data'!U34,"YYYY-MM-DD"),"")) | P33: =IF('JobPlanner Data'!O34="","","JobPlanner Data'!O34) | Q33: =IF('JobPlanner Data'!P34="","","JobPlanner Data'!P34)
A34: =IF('JobPlanner Data'!A35="","",IF(ISBLANK('JobPlanner Data'!A35),"",'JobPlanner Data'!A35)) | B34: =IF('JobPlanner Data'!B35="","",LOWER('JobPlanner Data'!B35)) | C34: =IF('JobPlanner Data'!D35<>"","JobPlanner Data'!D35,IF('JobPlanner Data'!F35<>"","JobPlanner Data'!F35,"")) | D34: =IF('JobPlanner Data'!J35="","",LOWER('JobPlanner Data'!J35)) | E34: =IF('JobPlanner Data'!C35="","",IFERROR(VLOOKUP('JobPlanner Data'!C35,'Company Lookup'!A:B,2,FALSE),"[NOT FOUND]")) | F34: =IF('JobPlanner Data'!G35="","",VALUE(SUBSTITUTE(SUBSTITUTE('JobPlanner Data'!G35,"$",""),",",""))) | G34: ="amount" | H34: =IF('JobPlanner Data'!L35="","","JobPlanner Data'!L35) | I34: =IF('JobPlanner Data'!H35="","","JobPlanner Data'!H35) | J34: =IF('JobPlanner Data'!N35="","",IF(ISNUMBER('JobPlanner Data'!N35),TEXT('JobPlanner Data'!N35,"YYYY-MM-DD"),"")) | K34: =IF('JobPlanner Data'!Q35="","",IF(ISNUMBER('JobPlanner Data'!Q35),TEXT('JobPlanner Data'!Q35,"YYYY-MM-DD"),"")) | L34: =IF('JobPlanner Data'!I35<>"",IF(ISNUMBER('JobPlanner Data'!I35),TEXT('JobPlanner Data'!I35,"YYYY-MM-DD"),""),IF('JobPlanner Data'!T35<>"",IF(ISNUMBER('JobPlanner Data'!T35),TEXT('JobPlanner Data'!T35,"YYYY-MM-DD"),""),"")) | M34: =IF('JobPlanner Data'!S35="","",IF(ISNUMBER('JobPlanner Data'!S35),TEXT('JobPlanner Data'!S35,"YYYY-MM-DD"),"")) | N34: =IF('JobPlanner Data'!R35="","",IF(ISNUMBER('JobPlanner Data'!R35),TEXT('JobPlanner Data'!R35,"YYYY-MM-DD"),"")) | O34: =IF('JobPlanner Data'!U35="","",IF(ISNUMBER('JobPlanner Data'!U35),TEXT('JobPlanner Data'!U35,"YYYY-MM-DD"),"")) | P34: =IF('JobPlanner Data'!O35="","","JobPlanner Data'!O35) | Q34: =IF('JobPlanner Data'!P35="","","JobPlanner Data'!P35)
A35: =IF('JobPlanner Data'!A36="","",IF(ISBLANK('JobPlanner Data'!A36),"",'JobPlanner Data'!A36)) | B35: =IF('JobPlanner Data'!B36="","",LOWER('JobPlanner Data'!B36)) | C35: =IF('JobPlanner Data'!D36<>"","JobPlanner Data'!D36,IF('JobPlanner Data'!F36<>"","JobPlanner Data'!F36,"")) | D35: =IF('JobPlanner Data'!J36="","",LOWER('JobPlanner Data'!J36)) | E35: =IF('JobPlanner Data'!C36="","",IFERROR(VLOOKUP('JobPlanner Data'!C36,'Company Lookup'!A:B,2,FALSE),"[NOT FOUND]")) | F35: =IF('JobPlanner Data'!G36="","",VALUE(SUBSTITUTE(SUBSTITUTE('JobPlanner Data'!G36,"$",""),",",""))) | G35: ="amount" | H35: =IF('JobPlanner Data'!L36="","","JobPlanner Data'!L36) | I35: =IF('JobPlanner Data'!H36="","","JobPlanner Data'!H36) | J35: =IF('JobPlanner Data'!N36="","",IF(ISNUMBER('JobPlanner Data'!N36),TEXT('JobPlanner Data'!N36,"YYYY-MM-DD"),"")) | K35: =IF('JobPlanner Data'!Q36="","",IF(ISNUMBER('JobPlanner Data'!Q36),TEXT('JobPlanner Data'!Q36,"YYYY-MM-DD"),"")) | L35: =IF('JobPlanner Data'!I36<>"",IF(ISNUMBER('JobPlanner Data'!I36),TEXT('JobPlanner Data'!I36,"YYYY-MM-DD"),""),IF('JobPlanner Data'!T36<>"",IF(ISNUMBER('JobPlanner Data'!T36),TEXT('JobPlanner Data'!T36,"YYYY-MM-DD"),""),"")) | M35: =IF('JobPlanner Data'!S36="","",IF(ISNUMBER('JobPlanner Data'!S36),TEXT('JobPlanner Data'!S36,"YYYY-MM-DD"),"")) | N35: =IF('JobPlanner Data'!R36="","",IF(ISNUMBER('JobPlanner Data'!R36),TEXT('JobPlanner Data'!R36,"YYYY-MM-DD"),"")) | O35: =IF('JobPlanner Data'!U36="","",IF(ISNUMBER('JobPlanner Data'!U36),TEXT('JobPlanner Data'!U36,"YYYY-MM-DD"),"")) | P35: =IF('JobPlanner Data'!O36="","","JobPlanner Data'!O36) | Q35: =IF('JobPlanner Data'!P36="","","JobPlanner Data'!P36)
