Workbook
Name PrjName: Setup!$C$6
Name PrjNumber: Setup!$C$7
Name PrjAddress: Setup!$C$8
Name PrjId: Setup!$C$9
Name PayerName: Setup!$C$11
Name PayerAddress: Setup!$C$12
Name PayeeName: Setup!$C$14
Name PayeeAddress: Setup!$C$15
Name VendorId: Setup!$C$16
Name ThirdName: Setup!$C$18
Name ContractNo: Setup!$C$20
Name ContractDate: Setup!$C$21
Name OrigContractSum: Setup!$C$22
Name ContractId: Setup!$C$23
Name RetPctWork: Setup!$C$25
Name RetPctMatl: Setup!$C$26
Name AppNo: Setup!$C$28
Name AppDate: Setup!$C$29
Name PeriodFrom: Setup!$C$30
Name PeriodTo: Setup!$C$31
Name CO_NetTotal: 'CO Log'!$I$47
Name CO_PrevAdd: 'CO Log'!$E$49
Name CO_PrevDed: 'CO Log'!$F$49
Name CO_ThisAdd: 'CO Log'!$E$50
Name CO_ThisDed: 'CO Log'!$F$50
Name SOV_ScheduledValue: 'Schedule of Values'!$D$67
Name SOV_WorkPrevious: 'Schedule of Values'!$E$67
Name SOV_WorkThisPeriod: 'Schedule of Values'!$F$67
Name SOV_MaterialsStored: 'Schedule of Values'!$G$67
Name SOV_TotalCompleted: 'Schedule of Values'!$H$67
Name SOV_BalanceToFinish: 'Schedule of Values'!$J$67
Name SOV_RetWorkPrior: 'Schedule of Values'!$L$67
Name SOV_RetWorkThis: 'Schedule of Values'!$M$67
Name SOV_RetWorkReleased: 'Schedule of Values'!$N$67
Name SOV_RetMatlPrior: 'Schedule of Values'!$P$67
Name SOV_RetMatlThis: 'Schedule of Values'!$Q$67
Name SOV_RetMatlReleased: 'Schedule of Values'!$R$67
Name SOV_RetTotal: 'Schedule of Values'!$S$67
Name SOV_ChangeOrders: 'Schedule of Values'!$D$65
Name APP_ContractSumToDate: 'Payment Application'!$E$17
Name APP_TotalEarnedLessRet: 'Payment Application'!$E$23
Name APP_CurrentPaymentDue: 'Payment Application'!$E$25

Sheet README
B2: ALLEATO GROUP BILLING TEMPLATE — SUBCONTRACTOR BILLING
B3: Your partner from the ground up. · www.alleatogroup.com
B4: WHAT THIS IS
B5: Alleato Group’s standard billing package: Form APP (Application and Certificate for Payment), Form CS (Continuation Sheet) and Form CO (Change Order), built as live formulas so a pay application can be produced, checked and archived without retyping numbers.
B6: Direction of billing: Subcontractor → Contractor.
B7: SHEETS, IN THE ORDER YOU USE THEM
B8: • Setup — project, parties, contract sum, retainage rates, current application period. The only sheet where project data is typed.
B9: • CO Log — every change order. Status must read Approved or Executed to be picked up. The In Prior Application Y/N flag splits the change order summary between prior applications and this one.
B10: • Schedule of Values — the working sheet and the monthly data entry: Scheduled Value (col D), From Previous Application (col E), This Period (col F), Materials Presently Stored (col G), and the prior / released retainage columns. Everything else calculates. Wider than the Continuation Sheet because it carries the retainage detail the platform needs.
B11: • Continuation Sheet — Form CS. The same schedule of values in the standard columns A through I. Every cell is a formula from the Schedule of Values sheet; nothing is typed here. This is the copy you send out.
B12: • Payment Application — Form APP. Reads entirely from the Schedule of Values and CO Log. The only typed cell is Line 7, Less Previous Certificates for Payment.
B13: • Change Order — Form CO. One change order per sheet; duplicate the sheet as needed.
... B39: Your partner from the ground up.

Sheet Setup
B2: PROJECT & CONTRACT SETUP
B3: Fill the white cells once per contract. Every other sheet reads from here.
B5: PROJECT | E5: HOW THIS WORKBOOK IS WIRED
B6: Project Name | E6: 1. Setup — project, parties, contract sum, retainage rates. Type here only.
B7: Project Number | E7: 2. CO Log — log every change order. Feeds the change order summary.
B8: Project Address | E8: 3. Schedule of Values — the SOV and the monthly data entry.
B9: Alleato Project ID (projects.id) | E9: 4. Payment Application — reads from the SOV + CO Log. Only Line 7 is typed.
B10: CONTRACTOR — PAYING PARTY | E10: 5. Change Order — one per change. Copy the sheet as needed.
B11: Contractor Name | E11: MONTHLY ROLLOVER
B12: Contractor Address | E12: • Copy the workbook, bump Application No., set the new period dates.
B13: SUBCONTRACTOR — PAID PARTY | E13: • On the SOV, paste last month’s column H into column E as VALUES, clear F and G.
B14: Subcontractor Name | E14: • On the Payment Application, set Line 7 to last month’s Line 6.
B15: Subcontractor Address | E15: • On CO Log, flip "In Prior Application" to Y for change orders already billed.
B16: Vendor ID (companies.id) | E16: RETAINAGE
... B20: Subcontract Number | E20: ALLEATO GROUP standard billing forms — see the README sheet.
B21: Subcontract Date
B22: Original Contract Sum | C22: 0
B23: Alleato Contract ID
B24: RETAINAGE — DRIVES LINES 5A / 5B
B25: Retainage % — Completed Work (5a) | C25: 10
B26: Retainage % — Stored Materials (5b) | C26: 10
B27: CURRENT APPLICATION
B28: Application No. | C28: 1
B29: Application Date
B30: Period From
B31: Period To

Sheet CO Log
A1: CHANGE ORDER LOG
A2: One row per change order. Only rows with Status = Approved or Executed are picked up. "In Prior Application" = Y once the change order has appeared on a certified application.
A6: CO NO. | B6: DESCRIPTION | C6: DATE APPROVED | D6: STATUS | E6: ADDITIONS ($) | F6: DEDUCTIONS ($) | G6: SCHEDULE IMPACT (DAYS) | H6: IN PRIOR APPLICATION? (Y/N) | I6: NET ($)
I7: =IF(COUNT(E7:F7)=0,"",N(E7)-N(F7))
I8: =IF(COUNT(E8:F8)=0,"",N(E8)-N(F8))
I9: =IF(COUNT(E9:F9)=0,"",N(E9)-N(F9))
I10: =IF(COUNT(E10:F10)=0,"",N(E10)-N(F10))
I11: =IF(COUNT(E11:F11)=0,"",N(E11)-N(F11))
I12: =IF(COUNT(E12:F12)=0,"",N(E12)-N(F12))
I13: =IF(COUNT(E13:F13)=0,"",N(E13)-N(F13))
I14: =IF(COUNT(E14:F14)=0,"",N(E14)-N(F14))
I15: =IF(COUNT(E15:F15)=0,"",N(E15)-N(F15))
I16: =IF(COUNT(E16:F16)=0,"",N(E16)-N(F16))
I17: =IF(COUNT(E17:F17)=0,"",N(E17)-N(F17))
I18: =IF(COUNT(E18:F18)=0,"",N(E18)-N(F18))
... I46: =IF(COUNT(E46:F46)=0,"",N(E46)-N(F46))
B47: TOTALS — APPROVED / EXECUTED ONLY | E47: =SUMPRODUCT((($D$7:$D$46="Approved")+($D$7:$D$46="Executed"))*N($E$7:$E$46)) | F47: =SUMPRODUCT((($D$7:$D$46="Approved")+($D$7:$D$46="Executed"))*N($F$7:$F$46)) | I47: =SUMPRODUCT((($D$7:$D$46="Approved")+($D$7:$D$46="Executed"))*N($I$7:$I$46))
B49: Approved in previous applications (In Prior = Y) | E49: =SUMIFS($E$7:$E$46,$H$7:$H$46,"Y",$D$7:$D$46,"Approved")+SUMIFS($E$7:$E$46,$H$7:$H$46,"Y",$D$7:$D$46,"Executed") | F49: =SUMIFS($F$7:$F$46,$H$7:$H$46,"Y",$D$7:$D$46,"Approved")+SUMIFS($F$7:$F$46,$H$7:$H$46,"Y",$D$7:$D$46,"Executed")
B50: Approved this application (In Prior = N) | E50: =SUMIFS($E$7:$E$46,$H$7:$H$46,"N",$D$7:$D$46,"Approved")+SUMIFS($E$7:$E$46,$H$7:$H$46,"N",$D$7:$D$46,"Executed") | F50: =SUMIFS($F$7:$F$46,$H$7:$H$46,"N",$D$7:$D$46,"Approved")+SUMIFS($F$7:$F$46,$H$7:$H$46,"N",$D$7:$D$46,"Executed")

Sheet Schedule of Values
A1: CONTINUATION SHEET — SCHEDULE OF VALUES
A2: Working schedule of values. Feeds the Continuation Sheet and the Payment Application.
B4: PROJECT: | C4: =IF(PrjName="","",PrjName) | G4: APPLICATION NO.: | H4: =AppNo
B5: SUBCONTRACTOR: | C5: =IF(PayeeName="","",PayeeName) | G5: PERIOD TO: | H5: =IF(PeriodTo="","",PeriodTo)
B6: SUBCONTRACT NO.: | C6: =IF(ContractNo="","",ContractNo) | G6: APP. DATE: | H6: =IF(AppDate="","",AppDate)
A9: A | B9: B | D9: C | E9: D | F9: E | G9: F | H9: G | I9: G/C | J9: H | K9: I | L9: I | M9: I | N9: I | O9: I | P9: I | Q9: I | R9: I | S9: I
A10: ITEM NO. | B10: DESCRIPTION OF WORK | C10: BUDGET CODE | D10: SCHEDULED VALUE | E10: WORK COMPLETED FROM PREVIOUS APPLICATION | F10: WORK COMPLETED THIS PERIOD | G10: MATERIALS PRESENTLY STORED | H10: TOTAL COMPLETED AND STORED TO DATE | I10: % | J10: BALANCE TO FINISH | K10: RET % WORK | L10: RET $ WORK PRIOR | M10: RET $ WORK THIS PERIOD | N10: RET $ WORK RELEASED | O10: RET % MATL | P10: RET $ MATL PRIOR | Q10: RET $ MATL THIS PERIOD | R10: RET $ MATL RELEASED | S10: TOTAL RETAINAGE HELD
A11: BASE CONTRACT
H12: =IF(COUNTA(A12:C12)+COUNT(D12:G12)=0,"",N(E12)+N(F12)+N(G12)) | I12: =IF(N(D12)=0,"",H12/D12*100) | J12: =IF(COUNTA(A12:C12)+COUNT(D12:G12)=0,"",N(D12)-N(H12)) | K12: =IF(COUNTA(A12:C12)+COUNT(D12:G12)=0,"",RetPctWork) | M12: =IF(COUNTA(A12:C12)+COUNT(D12:G12)=0,"",N(F12)*N(K12)/100) | O12: =IF(COUNTA(A12:C12)+COUNT(D12:G12)=0,"",RetPctMatl) | Q12: =IF(COUNTA(A12:C12)+COUNT(D12:G12)=0,"",N(G12)*N(O12)/100) | S12: =IF(COUNTA(A12:C12)+COUNT(D12:G12)=0,"",N(L12)+N(M12)-N(N12)+N(P12)+N(Q12)-N(R12))
H13: =IF(COUNTA(A13:C13)+COUNT(D13:G13)=0,"",N(E13)+N(F13)+N(G13)) | I13: =IF(N(D13)=0,"",H13/D13*100) | J13: =IF(COUNTA(A13:C13)+COUNT(D13:G13)=0,"",N(D13)-N(H13)) | K13: =IF(COUNTA(A13:C13)+COUNT(D13:G13)=0,"",RetPctWork) | M13: =IF(COUNTA(A13:C13)+COUNT(D13:G13)=0,"",N(F13)*N(K13)/100) | O13: =IF(COUNTA(A13:C13)+COUNT(D13:G13)=0,"",RetPctMatl) | Q13: =IF(COUNTA(A13:C13)+COUNT(D13:G13)=0,"",N(G13)*N(O13)/100) | S13: =IF(COUNTA(A13:C13)+COUNT(D13:G13)=0,"",N(L13)+N(M13)-N(N13)+N(P13)+N(Q13)-N(R13))
H14: =IF(COUNTA(A14:C14)+COUNT(D14:G14)=0,"",N(E14)+N(F14)+N(G14)) | I14: =IF(N(D14)=0,"",H14/D14*100) | J14: =IF(COUNTA(A14:C14)+COUNT(D14:G14)=0,"",N(D14)-N(H14)) | K14: =IF(COUNTA(A14:C14)+COUNT(D14:G14)=0,"",RetPctWork) | M14: =IF(COUNTA(A14:C14)+COUNT(D14:G14)=0,"",N(F14)*N(K14)/100) | O14: =IF(COUNTA(A14:C14)+COUNT(D14:G14)=0,"",RetPctMatl) | Q14: =IF(COUNTA(A14:C14)+COUNT(D14:G14)=0,"",N(G14)*N(O14)/100) | S14: =IF(COUNTA(A14:C14)+COUNT(D14:G14)=0,"",N(L14)+N(M14)-N(N14)+N(P14)+N(Q14)-N(R14))
H15: =IF(COUNTA(A15:C15)+COUNT(D15:G15)=0,"",N(E15)+N(F15)+N(G15)) | I15: =IF(N(D15)=0,"",H15/D15*100) | J15: =IF(COUNTA(A15:C15)+COUNT(D15:G15)=0,"",N(D15)-N(H15)) | K15: =IF(COUNTA(A15:C15)+COUNT(D15:G15)=0,"",RetPctWork) | M15: =IF(COUNTA(A15:C15)+COUNT(D15:G15)=0,"",N(F15)*N(K15)/100) | O15: =IF(COUNTA(A15:C15)+COUNT(D15:G15)=0,"",RetPctMatl) | Q15: =IF(COUNTA(A15:C15)+COUNT(D15:G15)=0,"",N(G15)*N(O15)/100) | S15: =IF(COUNTA(A15:C15)+COUNT(D15:G15)=0,"",N(L15)+N(M15)-N(N15)+N(P15)+N(Q15)-N(R15))
H16: =IF(COUNTA(A16:C16)+COUNT(D16:G16)=0,"",N(E16)+N(F16)+N(G16)) | I16: =IF(N(D16)=0,"",H16/D16*100) | J16: =IF(COUNTA(A16:C16)+COUNT(D16:G16)=0,"",N(D16)-N(H16)) | K16: =IF(COUNTA(A16:C16)+COUNT(D16:G16)=0,"",RetPctWork) | M16: =IF(COUNTA(A16:C16)+COUNT(D16:G16)=0,"",N(F16)*N(K16)/100) | O16: =IF(COUNTA(A16:C16)+COUNT(D16:G16)=0,"",RetPctMatl) | Q16: =IF(COUNTA(A16:C16)+COUNT(D16:G16)=0,"",N(G16)*N(O16)/100) | S16: =IF(COUNTA(A16:C16)+COUNT(D16:G16)=0,"",N(L16)+N(M16)-N(N16)+N(P16)+N(Q16)-N(R16))
H17: =IF(COUNTA(A17:C17)+COUNT(D17:G17)=0,"",N(E17)+N(F17)+N(G17)) | I17: =IF(N(D17)=0,"",H17/D17*100) | J17: =IF(COUNTA(A17:C17)+COUNT(D17:G17)=0,"",N(D17)-N(H17)) | K17: =IF(COUNTA(A17:C17)+COUNT(D17:G17)=0,"",RetPctWork) | M17: =IF(COUNTA(A17:C17)+COUNT(D17:G17)=0,"",N(F17)*N(K17)/100) | O17: =IF(COUNTA(A17:C17)+COUNT(D17:G17)=0,"",RetPctMatl) | Q17: =IF(COUNTA(A17:C17)+COUNT(D17:G17)=0,"",N(G17)*N(O17)/100) | S17: =IF(COUNTA(A17:C17)+COUNT(D17:G17)=0,"",N(L17)+N(M17)-N(N17)+N(P17)+N(Q17)-N(R17))
H18: =IF(COUNTA(A18:C18)+COUNT(D18:G18)=0,"",N(E18)+N(F18)+N(G18)) | I18: =IF(N(D18)=0,"",H18/D18*100) | J18: =IF(COUNTA(A18:C18)+COUNT(D18:G18)=0,"",N(D18)-N(H18)) | K18: =IF(COUNTA(A18:C18)+COUNT(D18:G18)=0,"",RetPctWork) | M18: =IF(COUNTA(A18:C18)+COUNT(D18:G18)=0,"",N(F18)*N(K18)/100) | O18: =IF(COUNTA(A18:C18)+COUNT(D18:G18)=0,"",RetPctMatl) | Q18: =IF(COUNTA(A18:C18)+COUNT(D18:G18)=0,"",N(G18)*N(O18)/100) | S18: =IF(COUNTA(A18:C18)+COUNT(D18:G18)=0,"",N(L18)+N(M18)-N(N18)+N(P18)+N(Q18)-N(R18))
H19: =IF(COUNTA(A19:C19)+COUNT(D19:G19)=0,"",N(E19)+N(F19)+N(G19)) | I19: =IF(N(D19)=0,"",H19/D19*100) | J19: =IF(COUNTA(A19:C19)+COUNT(D19:G19)=0,"",N(D19)-N(H19)) | K19: =IF(COUNTA(A19:C19)+COUNT(D19:G19)=0,"",RetPctWork) | M19: =IF(COUNTA(A19:C19)+COUNT(D19:G19)=0,"",N(F19)*N(K19)/100) | O19: =IF(COUNTA(A19:C19)+COUNT(D19:G19)=0,"",RetPctMatl) | Q19: =IF(COUNTA(A19:C19)+COUNT(D19:G19)=0,"",N(G19)*N(O19)/100) | S19: =IF(COUNTA(A19:C19)+COUNT(D19:G19)=0,"",N(L19)+N(M19)-N(N19)+N(P19)+N(Q19)-N(R19))
H20: =IF(COUNTA(A20:C20)+COUNT(D20:G20)=0,"",N(E20)+N(F20)+N(G20)) | I20: =IF(N(D20)=0,"",H20/D20*100) | J20: =IF(COUNTA(A20:C20)+COUNT(D20:G20)=0,"",N(D20)-N(H20)) | K20: =IF(COUNTA(A20:C20)+COUNT(D20:G20)=0,"",RetPctWork) | M20: =IF(COUNTA(A20:C20)+COUNT(D20:G20)=0,"",N(F20)*N(K20)/100) | O20: =IF(COUNTA(A20:C20)+COUNT(D20:G20)=0,"",RetPctMatl) | Q20: =IF(COUNTA(A20:C20)+COUNT(D20:G20)=0,"",N(G20)*N(O20)/100) | S20: =IF(COUNTA(A20:C20)+COUNT(D20:G20)=0,"",N(L20)+N(M20)-N(N20)+N(P20)+N(Q20)-N(R20))
H21: =IF(COUNTA(A21:C21)+COUNT(D21:G21)=0,"",N(E21)+N(F21)+N(G21)) | I21: =IF(N(D21)=0,"",H21/D21*100) | J21: =IF(COUNTA(A21:C21)+COUNT(D21:G21)=0,"",N(D21)-N(H21)) | K21: =IF(COUNTA(A21:C21)+COUNT(D21:G21)=0,"",RetPctWork) | M21: =IF(COUNTA(A21:C21)+COUNT(D21:G21)=0,"",N(F21)*N(K21)/100) | O21: =IF(COUNTA(A21:C21)+COUNT(D21:G21)=0,"",RetPctMatl) | Q21: =IF(COUNTA(A21:C21)+COUNT(D21:G21)=0,"",N(G21)*N(O21)/100) | S21: =IF(COUNTA(A21:C21)+COUNT(D21:G21)=0,"",N(L21)+N(M21)-N(N21)+N(P21)+N(Q21)-N(R21))
H22: =IF(COUNTA(A22:C22)+COUNT(D22:G22)=0,"",N(E22)+N(F22)+N(G22)) | I22: =IF(N(D22)=0,"",H22/D22*100) | J22: =IF(COUNTA(A22:C22)+COUNT(D22:G22)=0,"",N(D22)-N(H22)) | K22: =IF(COUNTA(A22:C22)+COUNT(D22:G22)=0,"",RetPctWork) | M22: =IF(COUNTA(A22:C22)+COUNT(D22:G22)=0,"",N(F22)*N(K22)/100) | O22: =IF(COUNTA(A22:C22)+COUNT(D22:G22)=0,"",RetPctMatl) | Q22: =IF(COUNTA(A22:C22)+COUNT(D22:G22)=0,"",N(G22)*N(O22)/100) | S22: =IF(COUNTA(A22:C22)+COUNT(D22:G22)=0,"",N(L22)+N(M22)-N(N22)+N(P22)+N(Q22)-N(R22))
H23: =IF(COUNTA(A23:C23)+COUNT(D23:G23)=0,"",N(E23)+N(F23)+N(G23)) | I23: =IF(N(D23)=0,"",H23/D23*100) | J23: =IF(COUNTA(A23:C23)+COUNT(D23:G23)=0,"",N(D23)-N(H23)) | K23: =IF(COUNTA(A23:C23)+COUNT(D23:G23)=0,"",RetPctWork) | M23: =IF(COUNTA(A23:C23)+COUNT(D23:G23)=0,"",N(F23)*N(K23)/100) | O23: =IF(COUNTA(A23:C23)+COUNT(D23:G23)=0,"",RetPctMatl) | Q23: =IF(COUNTA(A23:C23)+COUNT(D23:G23)=0,"",N(G23)*N(O23)/100) | S23: =IF(COUNTA(A23:C23)+COUNT(D23:G23)=0,"",N(L23)+N(M23)-N(N23)+N(P23)+N(Q23)-N(R23))
... H46: =IF(COUNTA(A46:C46)+COUNT(D46:G46)=0,"",N(E46)+N(F46)+N(G46)) | I46: =IF(N(D46)=0,"",H46/D46*100) | J46: =IF(COUNTA(A46:C46)+COUNT(D46:G46)=0,"",N(D46)-N(H46)) | K46: =IF(COUNTA(A46:C46)+COUNT(D46:G46)=0,"",RetPctWork) | M46: =IF(COUNTA(A46:C46)+COUNT(D46:G46)=0,"",N(F46)*N(K46)/100) | O46: =IF(COUNTA(A46:C46)+COUNT(D46:G46)=0,"",RetPctMatl) | Q46: =IF(COUNTA(A46:C46)+COUNT(D46:G46)=0,"",N(G46)*N(O46)/100) | S46: =IF(COUNTA(A46:C46)+COUNT(D46:G46)=0,"",N(L46)+N(M46)-N(N46)+N(P46)+N(Q46)-N(R46))
B47: SUBTOTAL — BASE CONTRACT | D47: =SUM(D12:D46) | E47: =SUM(E12:E46) | F47: =SUM(F12:F46) | G47: =SUM(G12:G46) | H47: =SUM(H12:H46) | I47: =IF(N(D47)=0,"",H47/D47*100) | J47: =SUM(J12:J46) | L47: =SUM(L12:L46) | M47: =SUM(M12:M46) | N47: =SUM(N12:N46) | P47: =SUM(P12:P46) | Q47: =SUM(Q12:Q46) | R47: =SUM(R12:R46) | S47: =SUM(S12:S46)
A49: APPROVED CHANGE ORDERS
H50: =IF(COUNTA(A50:C50)+COUNT(D50:G50)=0,"",N(E50)+N(F50)+N(G50)) | I50: =IF(N(D50)=0,"",H50/D50*100) | J50: =IF(COUNTA(A50:C50)+COUNT(D50:G50)=0,"",N(D50)-N(H50)) | K50: =IF(COUNTA(A50:C50)+COUNT(D50:G50)=0,"",RetPctWork) | M50: =IF(COUNTA(A50:C50)+COUNT(D50:G50)=0,"",N(F50)*N(K50)/100) | O50: =IF(COUNTA(A50:C50)+COUNT(D50:G50)=0,"",RetPctMatl) | Q50: =IF(COUNTA(A50:C50)+COUNT(D50:G50)=0,"",N(G50)*N(O50)/100) | S50: =IF(COUNTA(A50:C50)+COUNT(D50:G50)=0,"",N(L50)+N(M50)-N(N50)+N(P50)+N(Q50)-N(R50))
H51: =IF(COUNTA(A51:C51)+COUNT(D51:G51)=0,"",N(E51)+N(F51)+N(G51)) | I51: =IF(N(D51)=0,"",H51/D51*100) | J51: =IF(COUNTA(A51:C51)+COUNT(D51:G51)=0,"",N(D51)-N(H51)) | K51: =IF(COUNTA(A51:C51)+COUNT(D51:G51)=0,"",RetPctWork) | M51: =IF(COUNTA(A51:C51)+COUNT(D51:G51)=0,"",N(F51)*N(K51)/100) | O51: =IF(COUNTA(A51:C51)+COUNT(D51:G51)=0,"",RetPctMatl) | Q51: =IF(COUNTA(A51:C51)+COUNT(D51:G51)=0,"",N(G51)*N(O51)/100) | S51: =IF(COUNTA(A51:C51)+COUNT(D51:G51)=0,"",N(L51)+N(M51)-N(N51)+N(P51)+N(Q51)-N(R51))
H52: =IF(COUNTA(A52:C52)+COUNT(D52:G52)=0,"",N(E52)+N(F52)+N(G52)) | I52: =IF(N(D52)=0,"",H52/D52*100) | J52: =IF(COUNTA(A52:C52)+COUNT(D52:G52)=0,"",N(D52)-N(H52)) | K52: =IF(COUNTA(A52:C52)+COUNT(D52:G52)=0,"",RetPctWork) | M52: =IF(COUNTA(A52:C52)+COUNT(D52:G52)=0,"",N(F52)*N(K52)/100) | O52: =IF(COUNTA(A52:C52)+COUNT(D52:G52)=0,"",RetPctMatl) | Q52: =IF(COUNTA(A52:C52)+COUNT(D52:G52)=0,"",N(G52)*N(O52)/100) | S52: =IF(COUNTA(A52:C52)+COUNT(D52:G52)=0,"",N(L52)+N(M52)-N(N52)+N(P52)+N(Q52)-N(R52))
H53: =IF(COUNTA(A53:C53)+COUNT(D53:G53)=0,"",N(E53)+N(F53)+N(G53)) | I53: =IF(N(D53)=0,"",H53/D53*100) | J53: =IF(COUNTA(A53:C53)+COUNT(D53:G53)=0,"",N(D53)-N(H53)) | K53: =IF(COUNTA(A53:C53)+COUNT(D53:G53)=0,"",RetPctWork) | M53: =IF(COUNTA(A53:C53)+COUNT(D53:G53)=0,"",N(F53)*N(K53)/100) | O53: =IF(COUNTA(A53:C53)+COUNT(D53:G53)=0,"",RetPctMatl) | Q53: =IF(COUNTA(A53:C53)+COUNT(D53:G53)=0,"",N(G53)*N(O53)/100) | S53: =IF(COUNTA(A53:C53)+COUNT(D53:G53)=0,"",N(L53)+N(M53)-N(N53)+N(P53)+N(Q53)-N(R53))
H54: =IF(COUNTA(A54:C54)+COUNT(D54:G54)=0,"",N(E54)+N(F54)+N(G54)) | I54: =IF(N(D54)=0,"",H54/D54*100) | J54: =IF(COUNTA(A54:C54)+COUNT(D54:G54)=0,"",N(D54)-N(H54)) | K54: =IF(COUNTA(A54:C54)+COUNT(D54:G54)=0,"",RetPctWork) | M54: =IF(COUNTA(A54:C54)+COUNT(D54:G54)=0,"",N(F54)*N(K54)/100) | O54: =IF(COUNTA(A54:C54)+COUNT(D54:G54)=0,"",RetPctMatl) | Q54: =IF(COUNTA(A54:C54)+COUNT(D54:G54)=0,"",N(G54)*N(O54)/100) | S54: =IF(COUNTA(A54:C54)+COUNT(D54:G54)=0,"",N(L54)+N(M54)-N(N54)+N(P54)+N(Q54)-N(R54))
H55: =IF(COUNTA(A55:C55)+COUNT(D55:G55)=0,"",N(E55)+N(F55)+N(G55)) | I55: =IF(N(D55)=0,"",H55/D55*100) | J55: =IF(COUNTA(A55:C55)+COUNT(D55:G55)=0,"",N(D55)-N(H55)) | K55: =IF(COUNTA(A55:C55)+COUNT(D55:G55)=0,"",RetPctWork) | M55: =IF(COUNTA(A55:C55)+COUNT(D55:G55)=0,"",N(F55)*N(K55)/100) | O55: =IF(COUNTA(A55:C55)+COUNT(D55:G55)=0,"",RetPctMatl) | Q55: =IF(COUNTA(A55:C55)+COUNT(D55:G55)=0,"",N(G55)*N(O55)/100) | S55: =IF(COUNTA(A55:C55)+COUNT(D55:G55)=0,"",N(L55)+N(M55)-N(N55)+N(P55)+N(Q55)-N(R55))
H56: =IF(COUNTA(A56:C56)+COUNT(D56:G56)=0,"",N(E56)+N(F56)+N(G56)) | I56: =IF(N(D56)=0,"",H56/D56*100) | J56: =IF(COUNTA(A56:C56)+COUNT(D56:G56)=0,"",N(D56)-N(H56)) | K56: =IF(COUNTA(A56:C56)+COUNT(D56:G56)=0,"",RetPctWork) | M56: =IF(COUNTA(A56:C56)+COUNT(D56:G56)=0,"",N(F56)*N(K56)/100) | O56: =IF(COUNTA(A56:C56)+COUNT(D56:G56)=0,"",RetPctMatl) | Q56: =IF(COUNTA(A56:C56)+COUNT(D56:G56)=0,"",N(G56)*N(O56)/100) | S56: =IF(COUNTA(A56:C56)+COUNT(D56:G56)=0,"",N(L56)+N(M56)-N(N56)+N(P56)+N(Q56)-N(R56))
H57: =IF(COUNTA(A57:C57)+COUNT(D57:G57)=0,"",N(E57)+N(F57)+N(G57)) | I57: =IF(N(D57)=0,"",H57/D57*100) | J57: =IF(COUNTA(A57:C57)+COUNT(D57:G57)=0,"",N(D57)-N(H57)) | K57: =IF(COUNTA(A57:C57)+COUNT(D57:G57)=0,"",RetPctWork) | M57: =IF(COUNTA(A57:C57)+COUNT(D57:G57)=0,"",N(F57)*N(K57)/100) | O57: =IF(COUNTA(A57:C57)+COUNT(D57:G57)=0,"",RetPctMatl) | Q57: =IF(COUNTA(A57:C57)+COUNT(D57:G57)=0,"",N(G57)*N(O57)/100) | S57: =IF(COUNTA(A57:C57)+COUNT(D57:G57)=0,"",N(L57)+N(M57)-N(N57)+N(P57)+N(Q57)-N(R57))
H58: =IF(COUNTA(A58:C58)+COUNT(D58:G58)=0,"",N(E58)+N(F58)+N(G58)) | I58: =IF(N(D58)=0,"",H58/D58*100) | J58: =IF(COUNTA(A58:C58)+COUNT(D58:G58)=0,"",N(D58)-N(H58)) | K58: =IF(COUNTA(A58:C58)+COUNT(D58:G58)=0,"",RetPctWork) | M58: =IF(COUNTA(A58:C58)+COUNT(D58:G58)=0,"",N(F58)*N(K58)/100) | O58: =IF(COUNTA(A58:C58)+COUNT(D58:G58)=0,"",RetPctMatl) | Q58: =IF(COUNTA(A58:C58)+COUNT(D58:G58)=0,"",N(G58)*N(O58)/100) | S58: =IF(COUNTA(A58:C58)+COUNT(D58:G58)=0,"",N(L58)+N(M58)-N(N58)+N(P58)+N(Q58)-N(R58))
H59: =IF(COUNTA(A59:C59)+COUNT(D59:G59)=0,"",N(E59)+N(F59)+N(G59)) | I59: =IF(N(D59)=0,"",H59/D59*100) | J59: =IF(COUNTA(A59:C59)+COUNT(D59:G59)=0,"",N(D59)-N(H59)) | K59: =IF(COUNTA(A59:C59)+COUNT(D59:G59)=0,"",RetPctWork) | M59: =IF(COUNTA(A59:C59)+COUNT(D59:G59)=0,"",N(F59)*N(K59)/100) | O59: =IF(COUNTA(A59:C59)+COUNT(D59:G59)=0,"",RetPctMatl) | Q59: =IF(COUNTA(A59:C59)+COUNT(D59:G59)=0,"",N(G59)*N(O59)/100) | S59: =IF(COUNTA(A59:C59)+COUNT(D59:G59)=0,"",N(L59)+N(M59)-N(N59)+N(P59)+N(Q59)-N(R59))
H60: =IF(COUNTA(A60:C60)+COUNT(D60:G60)=0,"",N(E60)+N(F60)+N(G60)) | I60: =IF(N(D60)=0,"",H60/D60*100) | J60: =IF(COUNTA(A60:C60)+COUNT(D60:G60)=0,"",N(D60)-N(H60)) | K60: =IF(COUNTA(A60:C60)+COUNT(D60:G60)=0,"",RetPctWork) | M60: =IF(COUNTA(A60:C60)+COUNT(D60:G60)=0,"",N(F60)*N(K60)/100) | O60: =IF(COUNTA(A60:C60)+COUNT(D60:G60)=0,"",RetPctMatl) | Q60: =IF(COUNTA(A60:C60)+COUNT(D60:G60)=0,"",N(G60)*N(O60)/100) | S60: =IF(COUNTA(A60:C60)+COUNT(D60:G60)=0,"",N(L60)+N(M60)-N(N60)+N(P60)+N(Q60)-N(R60))
H61: =IF(COUNTA(A61:C61)+COUNT(D61:G61)=0,"",N(E61)+N(F61)+N(G61)) | I61: =IF(N(D61)=0,"",H61/D61*100) | J61: =IF(COUNTA(A61:C61)+COUNT(D61:G61)=0,"",N(D61)-N(H61)) | K61: =IF(COUNTA(A61:C61)+COUNT(D61:G61)=0,"",RetPctWork) | M61: =IF(COUNTA(A61:C61)+COUNT(D61:G61)=0,"",N(F61)*N(K61)/100) | O61: =IF(COUNTA(A61:C61)+COUNT(D61:G61)=0,"",RetPctMatl) | Q61: =IF(COUNTA(A61:C61)+COUNT(D61:G61)=0,"",N(G61)*N(O61)/100) | S61: =IF(COUNTA(A61:C61)+COUNT(D61:G61)=0,"",N(L61)+N(M61)-N(N61)+N(P61)+N(Q61)-N(R61))
... H64: =IF(COUNTA(A64:C64)+COUNT(D64:G64)=0,"",N(E64)+N(F64)+N(G64)) | I64: =IF(N(D64)=0,"",H64/D64*100) | J64: =IF(COUNTA(A64:C64)+COUNT(D64:G64)=0,"",N(D64)-N(H64)) | K64: =IF(COUNTA(A64:C64)+COUNT(D64:G64)=0,"",RetPctWork) | M64: =IF(COUNTA(A64:C64)+COUNT(D64:G64)=0,"",N(F64)*N(K64)/100) | O64: =IF(COUNTA(A64:C64)+COUNT(D64:G64)=0,"",RetPctMatl) | Q64: =IF(COUNTA(A64:C64)+COUNT(D64:G64)=0,"",N(G64)*N(O64)/100) | S64: =IF(COUNTA(A64:C64)+COUNT(D64:G64)=0,"",N(L64)+N(M64)-N(N64)+N(P64)+N(Q64)-N(R64))
B65: SUBTOTAL — APPROVED CHANGE ORDERS | D65: =SUM(D50:D64) | E65: =SUM(E50:E64) | F65: =SUM(F50:F64) | G65: =SUM(G50:G64) | H65: =SUM(H50:H64) | I65: =IF(N(D65)=0,"",H65/D65*100) | J65: =SUM(J50:J64) | L65: =SUM(L50:L64) | M65: =SUM(M50:M64) | N65: =SUM(N50:N64) | P65: =SUM(P50:P64) | Q65: =SUM(Q50:Q64) | R65: =SUM(R50:R64) | S65: =SUM(S50:S64)
B67: GRAND TOTAL — CARRIES TO THE PAYMENT APPLICATION | D67: =N(D47)+N(D65) | E67: =N(E47)+N(E65) | F67: =N(F47)+N(F65) | G67: =N(G47)+N(G65) | H67: =N(H47)+N(H65) | I67: =IF(N(D67)=0,"",H67/D67*100) | J67: =N(J47)+N(J65) | L67: =N(L47)+N(L65) | M67: =N(M47)+N(M65) | N67: =N(N47)+N(N65) | P67: =N(P47)+N(P65) | Q67: =N(Q47)+N(Q65) | R67: =N(R47)+N(R65) | S67: =N(S47)+N(S65)
B69: TIE-OUT — Scheduled Value total vs Line 3, Contract Sum to Date: | H69: =IF(ROUND(SOV_ScheduledValue-APP_ContractSumToDate,2)=0,"OK — ties","OUT OF BALANCE by "&TEXT(SOV_ScheduledValue-APP_ContractSumToDate,"#,##0.00"))

Sheet Continuation Sheet
A1: CONTINUATION SHEET
A2: Columns A through I only. Every value is a formula from the Schedule of Values sheet — do not type here. This is the transmittal copy.
A4: The Application and Certificate for Payment containing the Subcontractor’s signed certification is attached. Use Column I on Contracts where variable retainage for line items may apply. | F4: APPLICATION NO.: | H4: =IF(AppNo="","",AppNo)
F5: APPLICATION DATE: | H5: =IF(AppDate="","",AppDate)
F6: PERIOD TO: | H6: =IF(PeriodTo="","",PeriodTo)
F7: PROJECT NO.: | H7: =IF(PrjNumber="","",PrjNumber)
A8: A | B8: B | C8: C | D8: D | E8: E | F8: F | G8: G | I8: H | J8: I
A9: ITEM NO. | B9: DESCRIPTION OF WORK | C9: SCHEDULED VALUE | D9: WORK COMPLETED | F9: MATERIALS PRESENTLY STORED (NOT IN D OR E) | G9: TOTAL COMPLETED AND STORED TO DATE (D+E+F) | H9: % (G ÷ C) | I9: BALANCE TO FINISH (C – G) | J9: RETAINAGE (IF VARIABLE RATE)
D10: FROM PREVIOUS APPLICATION (D + E) | E10: THIS PERIOD
A11: BASE CONTRACT
A12: =IF('Schedule of Values'!A12="","",'Schedule of Values'!A12) | B12: =IF('Schedule of Values'!B12="","",'Schedule of Values'!B12) | C12: =IF('Schedule of Values'!D12="","",'Schedule of Values'!D12) | D12: =IF('Schedule of Values'!E12="","",'Schedule of Values'!E12) | E12: =IF('Schedule of Values'!F12="","",'Schedule of Values'!F12) | F12: =IF('Schedule of Values'!G12="","",'Schedule of Values'!G12) | G12: =IF('Schedule of Values'!H12="","",'Schedule of Values'!H12) | H12: =IF('Schedule of Values'!I12="","",'Schedule of Values'!I12) | I12: =IF('Schedule of Values'!J12="","",'Schedule of Values'!J12) | J12: =IF('Schedule of Values'!S12="","",'Schedule of Values'!S12)
A13: =IF('Schedule of Values'!A13="","",'Schedule of Values'!A13) | B13: =IF('Schedule of Values'!B13="","",'Schedule of Values'!B13) | C13: =IF('Schedule of Values'!D13="","",'Schedule of Values'!D13) | D13: =IF('Schedule of Values'!E13="","",'Schedule of Values'!E13) | E13: =IF('Schedule of Values'!F13="","",'Schedule of Values'!F13) | F13: =IF('Schedule of Values'!G13="","",'Schedule of Values'!G13) | G13: =IF('Schedule of Values'!H13="","",'Schedule of Values'!H13) | H13: =IF('Schedule of Values'!I13="","",'Schedule of Values'!I13) | I13: =IF('Schedule of Values'!J13="","",'Schedule of Values'!J13) | J13: =IF('Schedule of Values'!S13="","",'Schedule of Values'!S13)
A14: =IF('Schedule of Values'!A14="","",'Schedule of Values'!A14) | B14: =IF('Schedule of Values'!B14="","",'Schedule of Values'!B14) | C14: =IF('Schedule of Values'!D14="","",'Schedule of Values'!D14) | D14: =IF('Schedule of Values'!E14="","",'Schedule of Values'!E14) | E14: =IF('Schedule of Values'!F14="","",'Schedule of Values'!F14) | F14: =IF('Schedule of Values'!G14="","",'Schedule of Values'!G14) | G14: =IF('Schedule of Values'!H14="","",'Schedule of Values'!H14) | H14: =IF('Schedule of Values'!I14="","",'Schedule of Values'!I14) | I14: =IF('Schedule of Values'!J14="","",'Schedule of Values'!J14) | J14: =IF('Schedule of Values'!S14="","",'Schedule of Values'!S14)
A15: =IF('Schedule of Values'!A15="","",'Schedule of Values'!A15) | B15: =IF('Schedule of Values'!B15="","",'Schedule of Values'!B15) | C15: =IF('Schedule of Values'!D15="","",'Schedule of Values'!D15) | D15: =IF('Schedule of Values'!E15="","",'Schedule of Values'!E15) | E15: =IF('Schedule of Values'!F15="","",'Schedule of Values'!F15) | F15: =IF('Schedule of Values'!G15="","",'Schedule of Values'!G15) | G15: =IF('Schedule of Values'!H15="","",'Schedule of Values'!H15) | H15: =IF('Schedule of Values'!I15="","",'Schedule of Values'!I15) | I15: =IF('Schedule of Values'!J15="","",'Schedule of Values'!J15) | J15: =IF('Schedule of Values'!S15="","",'Schedule of Values'!S15)
A16: =IF('Schedule of Values'!A16="","",'Schedule of Values'!A16) | B16: =IF('Schedule of Values'!B16="","",'Schedule of Values'!B16) | C16: =IF('Schedule of Values'!D16="","",'Schedule of Values'!D16) | D16: =IF('Schedule of Values'!E16="","",'Schedule of Values'!E16) | E16: =IF('Schedule of Values'!F16="","",'Schedule of Values'!F16) | F16: =IF('Schedule of Values'!G16="","",'Schedule of Values'!G16) | G16: =IF('Schedule of Values'!H16="","",'Schedule of Values'!H16) | H16: =IF('Schedule of Values'!I16="","",'Schedule of Values'!I16) | I16: =IF('Schedule of Values'!J16="","",'Schedule of Values'!J16) | J16: =IF('Schedule of Values'!S16="","",'Schedule of Values'!S16)
A17: =IF('Schedule of Values'!A17="","",'Schedule of Values'!A17) | B17: =IF('Schedule of Values'!B17="","",'Schedule of Values'!B17) | C17: =IF('Schedule of Values'!D17="","",'Schedule of Values'!D17) | D17: =IF('Schedule of Values'!E17="","",'Schedule of Values'!E17) | E17: =IF('Schedule of Values'!F17="","",'Schedule of Values'!F17) | F17: =IF('Schedule of Values'!G17="","",'Schedule of Values'!G17) | G17: =IF('Schedule of Values'!H17="","",'Schedule of Values'!H17) | H17: =IF('Schedule of Values'!I17="","",'Schedule of Values'!I17) | I17: =IF('Schedule of Values'!J17="","",'Schedule of Values'!J17) | J17: =IF('Schedule of Values'!S17="","",'Schedule of Values'!S17)
A18: =IF('Schedule of Values'!A18="","",'Schedule of Values'!A18) | B18: =IF('Schedule of Values'!B18="","",'Schedule of Values'!B18) | C18: =IF('Schedule of Values'!D18="","",'Schedule of Values'!D18) | D18: =IF('Schedule of Values'!E18="","",'Schedule of Values'!E18) | E18: =IF('Schedule of Values'!F18="","",'Schedule of Values'!F18) | F18: =IF('Schedule of Values'!G18="","",'Schedule of Values'!G18) | G18: =IF('Schedule of Values'!H18="","",'Schedule of Values'!H18) | H18: =IF('Schedule of Values'!I18="","",'Schedule of Values'!I18) | I18: =IF('Schedule of Values'!J18="","",'Schedule of Values'!J18) | J18: =IF('Schedule of Values'!S18="","",'Schedule of Values'!S18)
A19: =IF('Schedule of Values'!A19="","",'Schedule of Values'!A19) | B19: =IF('Schedule of Values'!B19="","",'Schedule of Values'!B19) | C19: =IF('Schedule of Values'!D19="","",'Schedule of Values'!D19) | D19: =IF('Schedule of Values'!E19="","",'Schedule of Values'!E19) | E19: =IF('Schedule of Values'!F19="","",'Schedule of Values'!F19) | F19: =IF('Schedule of Values'!G19="","",'Schedule of Values'!G19) | G19: =IF('Schedule of Values'!H19="","",'Schedule of Values'!H19) | H19: =IF('Schedule of Values'!I19="","",'Schedule of Values'!I19) | I19: =IF('Schedule of Values'!J19="","",'Schedule of Values'!J19) | J19: =IF('Schedule of Values'!S19="","",'Schedule of Values'!S19)
A20: =IF('Schedule of Values'!A20="","",'Schedule of Values'!A20) | B20: =IF('Schedule of Values'!B20="","",'Schedule of Values'!B20) | C20: =IF('Schedule of Values'!D20="","",'Schedule of Values'!D20) | D20: =IF('Schedule of Values'!E20="","",'Schedule of Values'!E20) | E20: =IF('Schedule of Values'!F20="","",'Schedule of Values'!F20) | F20: =IF('Schedule of Values'!G20="","",'Schedule of Values'!G20) | G20: =IF('Schedule of Values'!H20="","",'Schedule of Values'!H20) | H20: =IF('Schedule of Values'!I20="","",'Schedule of Values'!I20) | I20: =IF('Schedule of Values'!J20="","",'Schedule of Values'!J20) | J20: =IF('Schedule of Values'!S20="","",'Schedule of Values'!S20)
A21: =IF('Schedule of Values'!A21="","",'Schedule of Values'!A21) | B21: =IF('Schedule of Values'!B21="","",'Schedule of Values'!B21) | C21: =IF('Schedule of Values'!D21="","",'Schedule of Values'!D21) | D21: =IF('Schedule of Values'!E21="","",'Schedule of Values'!E21) | E21: =IF('Schedule of Values'!F21="","",'Schedule of Values'!F21) | F21: =IF('Schedule of Values'!G21="","",'Schedule of Values'!G21) | G21: =IF('Schedule of Values'!H21="","",'Schedule of Values'!H21) | H21: =IF('Schedule of Values'!I21="","",'Schedule of Values'!I21) | I21: =IF('Schedule of Values'!J21="","",'Schedule of Values'!J21) | J21: =IF('Schedule of Values'!S21="","",'Schedule of Values'!S21)
A22: =IF('Schedule of Values'!A22="","",'Schedule of Values'!A22) | B22: =IF('Schedule of Values'!B22="","",'Schedule of Values'!B22) | C22: =IF('Schedule of Values'!D22="","",'Schedule of Values'!D22) | D22: =IF('Schedule of Values'!E22="","",'Schedule of Values'!E22) | E22: =IF('Schedule of Values'!F22="","",'Schedule of Values'!F22) | F22: =IF('Schedule of Values'!G22="","",'Schedule of Values'!G22) | G22: =IF('Schedule of Values'!H22="","",'Schedule of Values'!H22) | H22: =IF('Schedule of Values'!I22="","",'Schedule of Values'!I22) | I22: =IF('Schedule of Values'!J22="","",'Schedule of Values'!J22) | J22: =IF('Schedule of Values'!S22="","",'Schedule of Values'!S22)
A23: =IF('Schedule of Values'!A23="","",'Schedule of Values'!A23) | B23: =IF('Schedule of Values'!B23="","",'Schedule of Values'!B23) | C23: =IF('Schedule of Values'!D23="","",'Schedule of Values'!D23) | D23: =IF('Schedule of Values'!E23="","",'Schedule of Values'!E23) | E23: =IF('Schedule of Values'!F23="","",'Schedule of Values'!F23) | F23: =IF('Schedule of Values'!G23="","",'Schedule of Values'!G23) | G23: =IF('Schedule of Values'!H23="","",'Schedule of Values'!H23) | H23: =IF('Schedule of Values'!I23="","",'Schedule of Values'!I23) | I23: =IF('Schedule of Values'!J23="","",'Schedule of Values'!J23) | J23: =IF('Schedule of Values'!S23="","",'Schedule of Values'!S23)
... A46: =IF('Schedule of Values'!A46="","",'Schedule of Values'!A46) | B46: =IF('Schedule of Values'!B46="","",'Schedule of Values'!B46) | C46: =IF('Schedule of Values'!D46="","",'Schedule of Values'!D46) | D46: =IF('Schedule of Values'!E46="","",'Schedule of Values'!E46) | E46: =IF('Schedule of Values'!F46="","",'Schedule of Values'!F46) | F46: =IF('Schedule of Values'!G46="","",'Schedule of Values'!G46) | G46: =IF('Schedule of Values'!H46="","",'Schedule of Values'!H46) | H46: =IF('Schedule of Values'!I46="","",'Schedule of Values'!I46) | I46: =IF('Schedule of Values'!J46="","",'Schedule of Values'!J46) | J46: =IF('Schedule of Values'!S46="","",'Schedule of Values'!S46)
A47: =IF('Schedule of Values'!A47="","",'Schedule of Values'!A47) | B47: SUBTOTAL — BASE CONTRACT | C47: =IF('Schedule of Values'!D47="","",'Schedule of Values'!D47) | D47: =IF('Schedule of Values'!E47="","",'Schedule of Values'!E47) | E47: =IF('Schedule of Values'!F47="","",'Schedule of Values'!F47) | F47: =IF('Schedule of Values'!G47="","",'Schedule of Values'!G47) | G47: =IF('Schedule of Values'!H47="","",'Schedule of Values'!H47) | H47: =IF('Schedule of Values'!I47="","",'Schedule of Values'!I47) | I47: =IF('Schedule of Values'!J47="","",'Schedule of Values'!J47) | J47: =IF('Schedule of Values'!S47="","",'Schedule of Values'!S47)
A49: APPROVED CHANGE ORDERS
A50: =IF('Schedule of Values'!A50="","",'Schedule of Values'!A50) | B50: =IF('Schedule of Values'!B50="","",'Schedule of Values'!B50) | C50: =IF('Schedule of Values'!D50="","",'Schedule of Values'!D50) | D50: =IF('Schedule of Values'!E50="","",'Schedule of Values'!E50) | E50: =IF('Schedule of Values'!F50="","",'Schedule of Values'!F50) | F50: =IF('Schedule of Values'!G50="","",'Schedule of Values'!G50) | G50: =IF('Schedule of Values'!H50="","",'Schedule of Values'!H50) | H50: =IF('Schedule of Values'!I50="","",'Schedule of Values'!I50) | I50: =IF('Schedule of Values'!J50="","",'Schedule of Values'!J50) | J50: =IF('Schedule of Values'!S50="","",'Schedule of Values'!S50)
A51: =IF('Schedule of Values'!A51="","",'Schedule of Values'!A51) | B51: =IF('Schedule of Values'!B51="","",'Schedule of Values'!B51) | C51: =IF('Schedule of Values'!D51="","",'Schedule of Values'!D51) | D51: =IF('Schedule of Values'!E51="","",'Schedule of Values'!E51) | E51: =IF('Schedule of Values'!F51="","",'Schedule of Values'!F51) | F51: =IF('Schedule of Values'!G51="","",'Schedule of Values'!G51) | G51: =IF('Schedule of Values'!H51="","",'Schedule of Values'!H51) | H51: =IF('Schedule of Values'!I51="","",'Schedule of Values'!I51) | I51: =IF('Schedule of Values'!J51="","",'Schedule of Values'!J51) | J51: =IF('Schedule of Values'!S51="","",'Schedule of Values'!S51)
A52: =IF('Schedule of Values'!A52="","",'Schedule of Values'!A52) | B52: =IF('Schedule of Values'!B52="","",'Schedule of Values'!B52) | C52: =IF('Schedule of Values'!D52="","",'Schedule of Values'!D52) | D52: =IF('Schedule of Values'!E52="","",'Schedule of Values'!E52) | E52: =IF('Schedule of Values'!F52="","",'Schedule of Values'!F52) | F52: =IF('Schedule of Values'!G52="","",'Schedule of Values'!G52) | G52: =IF('Schedule of Values'!H52="","",'Schedule of Values'!H52) | H52: =IF('Schedule of Values'!I52="","",'Schedule of Values'!I52) | I52: =IF('Schedule of Values'!J52="","",'Schedule of Values'!J52) | J52: =IF('Schedule of Values'!S52="","",'Schedule of Values'!S52)
A53: =IF('Schedule of Values'!A53="","",'Schedule of Values'!A53) | B53: =IF('Schedule of Values'!B53="","",'Schedule of Values'!B53) | C53: =IF('Schedule of Values'!D53="","",'Schedule of Values'!D53) | D53: =IF('Schedule of Values'!E53="","",'Schedule of Values'!E53) | E53: =IF('Schedule of Values'!F53="","",'Schedule of Values'!F53) | F53: =IF('Schedule of Values'!G53="","",'Schedule of Values'!G53) | G53: =IF('Schedule of Values'!H53="","",'Schedule of Values'!H53) | H53: =IF('Schedule of Values'!I53="","",'Schedule of Values'!I53) | I53: =IF('Schedule of Values'!J53="","",'Schedule of Values'!J53) | J53: =IF('Schedule of Values'!S53="","",'Schedule of Values'!S53)
A54: =IF('Schedule of Values'!A54="","",'Schedule of Values'!A54) | B54: =IF('Schedule of Values'!B54="","",'Schedule of Values'!B54) | C54: =IF('Schedule of Values'!D54="","",'Schedule of Values'!D54) | D54: =IF('Schedule of Values'!E54="","",'Schedule of Values'!E54) | E54: =IF('Schedule of Values'!F54="","",'Schedule of Values'!F54) | F54: =IF('Schedule of Values'!G54="","",'Schedule of Values'!G54) | G54: =IF('Schedule of Values'!H54="","",'Schedule of Values'!H54) | H54: =IF('Schedule of Values'!I54="","",'Schedule of Values'!I54) | I54: =IF('Schedule of Values'!J54="","",'Schedule of Values'!J54) | J54: =IF('Schedule of Values'!S54="","",'Schedule of Values'!S54)
A55: =IF('Schedule of Values'!A55="","",'Schedule of Values'!A55) | B55: =IF('Schedule of Values'!B55="","",'Schedule of Values'!B55) | C55: =IF('Schedule of Values'!D55="","",'Schedule of Values'!D55) | D55: =IF('Schedule of Values'!E55="","",'Schedule of Values'!E55) | E55: =IF('Schedule of Values'!F55="","",'Schedule of Values'!F55) | F55: =IF('Schedule of Values'!G55="","",'Schedule of Values'!G55) | G55: =IF('Schedule of Values'!H55="","",'Schedule of Values'!H55) | H55: =IF('Schedule of Values'!I55="","",'Schedule of Values'!I55) | I55: =IF('Schedule of Values'!J55="","",'Schedule of Values'!J55) | J55: =IF('Schedule of Values'!S55="","",'Schedule of Values'!S55)
A56: =IF('Schedule of Values'!A56="","",'Schedule of Values'!A56) | B56: =IF('Schedule of Values'!B56="","",'Schedule of Values'!B56) | C56: =IF('Schedule of Values'!D56="","",'Schedule of Values'!D56) | D56: =IF('Schedule of Values'!E56="","",'Schedule of Values'!E56) | E56: =IF('Schedule of Values'!F56="","",'Schedule of Values'!F56) | F56: =IF('Schedule of Values'!G56="","",'Schedule of Values'!G56) | G56: =IF('Schedule of Values'!H56="","",'Schedule of Values'!H56) | H56: =IF('Schedule of Values'!I56="","",'Schedule of Values'!I56) | I56: =IF('Schedule of Values'!J56="","",'Schedule of Values'!J56) | J56: =IF('Schedule of Values'!S56="","",'Schedule of Values'!S56)
A57: =IF('Schedule of Values'!A57="","",'Schedule of Values'!A57) | B57: =IF('Schedule of Values'!B57="","",'Schedule of Values'!B57) | C57: =IF('Schedule of Values'!D57="","",'Schedule of Values'!D57) | D57: =IF('Schedule of Values'!E57="","",'Schedule of Values'!E57) | E57: =IF('Schedule of Values'!F57="","",'Schedule of Values'!F57) | F57: =IF('Schedule of Values'!G57="","",'Schedule of Values'!G57) | G57: =IF('Schedule of Values'!H57="","",'Schedule of Values'!H57) | H57: =IF('Schedule of Values'!I57="","",'Schedule of Values'!I57) | I57: =IF('Schedule of Values'!J57="","",'Schedule of Values'!J57) | J57: =IF('Schedule of Values'!S57="","",'Schedule of Values'!S57)
A58: =IF('Schedule of Values'!A58="","",'Schedule of Values'!A58) | B58: =IF('Schedule of Values'!B58="","",'Schedule of Values'!B58) | C58: =IF('Schedule of Values'!D58="","",'Schedule of Values'!D58) | D58: =IF('Schedule of Values'!E58="","",'Schedule of Values'!E58) | E58: =IF('Schedule of Values'!F58="","",'Schedule of Values'!F58) | F58: =IF('Schedule of Values'!G58="","",'Schedule of Values'!G58) | G58: =IF('Schedule of Values'!H58="","",'Schedule of Values'!H58) | H58: =IF('Schedule of Values'!I58="","",'Schedule of Values'!I58) | I58: =IF('Schedule of Values'!J58="","",'Schedule of Values'!J58) | J58: =IF('Schedule of Values'!S58="","",'Schedule of Values'!S58)
A59: =IF('Schedule of Values'!A59="","",'Schedule of Values'!A59) | B59: =IF('Schedule of Values'!B59="","",'Schedule of Values'!B59) | C59: =IF('Schedule of Values'!D59="","",'Schedule of Values'!D59) | D59: =IF('Schedule of Values'!E59="","",'Schedule of Values'!E59) | E59: =IF('Schedule of Values'!F59="","",'Schedule of Values'!F59) | F59: =IF('Schedule of Values'!G59="","",'Schedule of Values'!G59) | G59: =IF('Schedule of Values'!H59="","",'Schedule of Values'!H59) | H59: =IF('Schedule of Values'!I59="","",'Schedule of Values'!I59) | I59: =IF('Schedule of Values'!J59="","",'Schedule of Values'!J59) | J59: =IF('Schedule of Values'!S59="","",'Schedule of Values'!S59)
A60: =IF('Schedule of Values'!A60="","",'Schedule of Values'!A60) | B60: =IF('Schedule of Values'!B60="","",'Schedule of Values'!B60) | C60: =IF('Schedule of Values'!D60="","",'Schedule of Values'!D60) | D60: =IF('Schedule of Values'!E60="","",'Schedule of Values'!E60) | E60: =IF('Schedule of Values'!F60="","",'Schedule of Values'!F60) | F60: =IF('Schedule of Values'!G60="","",'Schedule of Values'!G60) | G60: =IF('Schedule of Values'!H60="","",'Schedule of Values'!H60) | H60: =IF('Schedule of Values'!I60="","",'Schedule of Values'!I60) | I60: =IF('Schedule of Values'!J60="","",'Schedule of Values'!J60) | J60: =IF('Schedule of Values'!S60="","",'Schedule of Values'!S60)
A61: =IF('Schedule of Values'!A61="","",'Schedule of Values'!A61) | B61: =IF('Schedule of Values'!B61="","",'Schedule of Values'!B61) | C61: =IF('Schedule of Values'!D61="","",'Schedule of Values'!D61) | D61: =IF('Schedule of Values'!E61="","",'Schedule of Values'!E61) | E61: =IF('Schedule of Values'!F61="","",'Schedule of Values'!F61) | F61: =IF('Schedule of Values'!G61="","",'Schedule of Values'!G61) | G61: =IF('Schedule of Values'!H61="","",'Schedule of Values'!H61) | H61: =IF('Schedule of Values'!I61="","",'Schedule of Values'!I61) | I61: =IF('Schedule of Values'!J61="","",'Schedule of Values'!J61) | J61: =IF('Schedule of Values'!S61="","",'Schedule of Values'!S61)
... A64: =IF('Schedule of Values'!A64="","",'Schedule of Values'!A64) | B64: =IF('Schedule of Values'!B64="","",'Schedule of Values'!B64) | C64: =IF('Schedule of Values'!D64="","",'Schedule of Values'!D64) | D64: =IF('Schedule of Values'!E64="","",'Schedule of Values'!E64) | E64: =IF('Schedule of Values'!F64="","",'Schedule of Values'!F64) | F64: =IF('Schedule of Values'!G64="","",'Schedule of Values'!G64) | G64: =IF('Schedule of Values'!H64="","",'Schedule of Values'!H64) | H64: =IF('Schedule of Values'!I64="","",'Schedule of Values'!I64) | I64: =IF('Schedule of Values'!J64="","",'Schedule of Values'!J64) | J64: =IF('Schedule of Values'!S64="","",'Schedule of Values'!S64)
A65: =IF('Schedule of Values'!A65="","",'Schedule of Values'!A65) | B65: SUBTOTAL — APPROVED CHANGE ORDERS | C65: =IF('Schedule of Values'!D65="","",'Schedule of Values'!D65) | D65: =IF('Schedule of Values'!E65="","",'Schedule of Values'!E65) | E65: =IF('Schedule of Values'!F65="","",'Schedule of Values'!F65) | F65: =IF('Schedule of Values'!G65="","",'Schedule of Values'!G65) | G65: =IF('Schedule of Values'!H65="","",'Schedule of Values'!H65) | H65: =IF('Schedule of Values'!I65="","",'Schedule of Values'!I65) | I65: =IF('Schedule of Values'!J65="","",'Schedule of Values'!J65) | J65: =IF('Schedule of Values'!S65="","",'Schedule of Values'!S65)
A67: =IF('Schedule of Values'!A67="","",'Schedule of Values'!A67) | B67: GRAND TOTAL | C67: =IF('Schedule of Values'!D67="","",'Schedule of Values'!D67) | D67: =IF('Schedule of Values'!E67="","",'Schedule of Values'!E67) | E67: =IF('Schedule of Values'!F67="","",'Schedule of Values'!F67) | F67: =IF('Schedule of Values'!G67="","",'Schedule of Values'!G67) | G67: =IF('Schedule of Values'!H67="","",'Schedule of Values'!H67) | H67: =IF('Schedule of Values'!I67="","",'Schedule of Values'!I67) | I67: =IF('Schedule of Values'!J67="","",'Schedule of Values'!J67) | J67: =IF('Schedule of Values'!S67="","",'Schedule of Values'!S67)
...

Sheet Payment Application
B1: SUBCONTRACTOR APPLICATION FOR PAYMENT
B2: Form APP · Subcontract / Commitment · Subcontractor to Contractor
B4: TO CONTRACTOR: | D4: =IF(PayerName="","",PayerName) | F4: APPLICATION NO.: | H4: =IF(AppNo="","",AppNo)
D5: =IF(PayerAddress="","",PayerAddress) | F5: APPLICATION DATE: | H5: =IF(AppDate="","",AppDate)
B6: FROM SUBCONTRACTOR: | D6: =IF(PayeeName="","",PayeeName) | F6: PERIOD FROM: | H6: =IF(PeriodFrom="","",PeriodFrom)
D7: =IF(PayeeAddress="","",PayeeAddress) | F7: PERIOD TO: | H7: =IF(PeriodTo="","",PeriodTo)
B8: PROJECT: | D8: =IF(PrjName="","",PrjName) | F8: SUBCONTRACT NO.: | H8: =IF(ContractNo="","",ContractNo)
B9: PROJECT NO.: | D9: =IF(PrjNumber="","",PrjNumber) | F9: SUBCONTRACT DATE: | H9: =IF(ContractDate="","",ContractDate)
B10: VIA PROJECT MANAGER: | D10: =IF(ThirdName="","",ThirdName) | F10: ALLEATO PROJECT ID: | H10: =IF(PrjId="","",PrjId)
B12: SUBCONTRACTOR’S APPLICATION FOR PAYMENT | G12: CHANGE ORDER SUMMARY
B13: Application is made for payment, as shown below, in connection with the Contract.
H14: ADDITIONS | I14: DEDUCTIONS
B15: 1 | C15: ORIGINAL CONTRACT SUM | E15: =OrigContractSum | G15: Total changes approved in previous applications by Contractor | H15: =CO_PrevAdd | I15: =CO_PrevDed
B16: 2 | C16: Net change by Change Orders | E16: =CO_NetTotal | G16: Total approved this application | H16: =CO_ThisAdd | I16: =CO_ThisDed
B17: 3 | C17: CONTRACT SUM TO DATE (Line 1 ± Line 2) | E17: =N(E15)+N(E16) | G17: TOTALS | H17: =SUM(H15:H16) | I17: =SUM(I15:I16)
B18: 4 | C18: TOTAL COMPLETED AND STORED TO DATE (Continuation Sheet, column G) | E18: =SOV_TotalCompleted | G18: NET CHANGE BY CHANGE ORDERS | H18: =N(H17)-N(I17)
B19: 5 | C19: RETAINAGE:
B20: 5a | C20: of Completed Work (SOV prior + this period − released) | D20: =RetPctWork | E20: =SOV_RetWorkPrior+SOV_RetWorkThis-SOV_RetWorkReleased | G20: =IF(ROUND(N(H18)-N(E16),2)=0,"Net change ties to Line 2.","WARNING: Line 2 does not tie to the change order summary.")
B21: 5b | C21: of Stored Material (SOV prior + this period − released) | D21: =RetPctMatl | E21: =SOV_RetMatlPrior+SOV_RetMatlThis-SOV_RetMatlReleased
C22: Total Retainage (Lines 5a + 5b = SOV column S) | E22: =SOV_RetTotal | G22: =IF(ROUND(N(E20)+N(E21)-N(E22),2)=0,"Retainage 5a + 5b ties to SOV column S.","WARNING: retainage does not foot to SOV column S.")
B23: 6 | C23: TOTAL EARNED LESS RETAINAGE (Line 4 less Line 5 Total) | E23: =N(E18)-N(E22) | G23: PERCENT COMPLETE | I23: =IF(N(E17)=0,"",N(E18)/N(E17)*100)
B24: 7 | C24: LESS PREVIOUS CERTIFICATES FOR PAYMENT (Line 6 from prior Certificate) | E24: 0 | G24: RETAINAGE HELD TO DATE | I24: =N(E22)
B25: 8 | C25: CURRENT PAYMENT DUE | E25: =N(E23)-N(E24)
B26: 9 | C26: BALANCE TO FINISH, INCLUDING RETAINAGE (Line 3 less Line 6) | E26: =N(E17)-N(E23)
B29: SUBCONTRACTOR’S CERTIFICATION
B30: The undersigned subcontractor certifies that, to the best of its knowledge, information and belief, the Work covered by this Application for Payment has been completed in accordance with the Contract Documents, that all amounts have been paid by the subcontractor for Work for which previous Certificates for Payment were issued and payments received from the contractor, and that the current payment shown herein is now due.
B34: SUBCONTRACTOR (firm): | G34: State of:
B36: By (signature): | G36: County of:
B38: Printed name / title: | G38: Subscribed and sworn to before me this ____ day of ____________, 20____.
B40: Date: | G40: Notary Public:
B43: CONTRACTOR’S APPROVAL FOR PAYMENT
B44: In accordance with the Contract Documents and based on observations at the site and the data comprising this Application, the contractor certifies to the contractor that the Work has progressed as indicated, that the quality of the Work is in accordance with the Contract Documents, and that the subcontractor is entitled to payment of the AMOUNT CERTIFIED.
B48: AMOUNT CERTIFIED | E48: =APP_CurrentPaymentDue
B49: If AMOUNT CERTIFIED differs from CURRENT PAYMENT DUE, attach an explanation and initial every figure changed on this Application and on the Continuation Sheet.
B52: CONTRACTOR (firm):
B54: By (signature):
B56: Date:
B59: This Certificate is not negotiable. The AMOUNT CERTIFIED is payable only to the subcontractor named herein. Issuance, payment and acceptance of payment are without prejudice to any rights of the contractor or subcontractor under the Contract.

Sheet Change Order
B1: CHANGE ORDER
B2: Form CO · Contractor ↔ Subcontractor
B4: PROJECT: | C4: =IF(PrjName="","",PrjName) | E4: CHANGE ORDER NO.:
B5: PROJECT NO.: | C5: =IF(PrjNumber="","",PrjNumber) | E5: DATE:
B6: CONTRACTOR: | C6: =IF(PayerName="","",PayerName) | E6: SUBCONTRACT NO.: | F6: =IF(ContractNo="","",ContractNo)
B7: SUBCONTRACTOR: | C7: =IF(PayeeName="","",PayeeName) | E7: SUBCONTRACT DATE: | F7: =IF(ContractDate="","",ContractDate)
B8: PROJECT MANAGER: | C8: =IF(ThirdName="","",ThirdName) | E8: ALLEATO PROJECT ID: | F8: =IF(PrjId="","",PrjId)
B10: THE CONTRACT IS CHANGED AS FOLLOWS
B11: Describe the change in scope, the reason for the change, and reference the authorizing document (RFI, ASI, bulletin, field directive, CCD).
B21: COST BREAKDOWN
B22: DESCRIPTION | C22: BUDGET CODE | D22: QTY | E22: UOM | F22: UNIT COST | G22: AMOUNT
G23: =IF(COUNT(D23,F23)=2,N(D23)*N(F23),"")
G24: =IF(COUNT(D24,F24)=2,N(D24)*N(F24),"")
G25: =IF(COUNT(D25,F25)=2,N(D25)*N(F25),"")
G26: =IF(COUNT(D26,F26)=2,N(D26)*N(F26),"")
G27: =IF(COUNT(D27,F27)=2,N(D27)*N(F27),"")
G28: =IF(COUNT(D28,F28)=2,N(D28)*N(F28),"")
G29: =IF(COUNT(D29,F29)=2,N(D29)*N(F29),"")
G30: =IF(COUNT(D30,F30)=2,N(D30)*N(F30),"")
G31: =IF(COUNT(D31,F31)=2,N(D31)*N(F31),"")
G32: =IF(COUNT(D32,F32)=2,N(D32)*N(F32),"")
G33: =IF(COUNT(D33,F33)=2,N(D33)*N(F33),"")
G34: =IF(COUNT(D34,F34)=2,N(D34)*N(F34),"")
B35: TOTAL THIS CHANGE ORDER | G35: =SUM(G23:G34)
B36: If AMOUNT is entered directly without qty × unit cost, put it in the AMOUNT column and leave QTY / UNIT COST blank.
B38: CONTRACT SUM ADJUSTMENT
B39: The original Contract Sum was | F39: =OrigContractSum
B40: Net change by previously authorized Change Orders | F40: 0
B41: The Contract Sum prior to this Change Order was | F41: =N(F39)+N(F40)
B42: The Contract Sum will be increased / (decreased) by this Change Order in the amount of | F42: =N(G35)
B43: The new Contract Sum including this Change Order will be | F43: =N(F41)+N(F42)
B45: The Contract Time will be increased / (decreased) by | G45: calendar days
B46: The date of Substantial Completion as of this Change Order is
B48: NOTE: This Change Order does not include changes in the Contract Sum, Contract Time or Guaranteed Maximum Price that have been authorized by Construction Change Directive until the cost and time have been agreed upon by both parties.
B51: NOT VALID UNTIL SIGNED BY ALL PARTIES BELOW
B53: CONTRACTOR | E53: SUBCONTRACTOR
B55: (firm name) | E55: (firm name)
B58: BY (signature) | E58: BY (signature)
B61: (printed name and title) | E61: (printed name and title)
B64: DATE | E64: DATE
